<sdf version='1.5'>
  <world name='default'>
    <light name='sun' type='directional'>
      <cast_shadows>1</cast_shadows>
      <pose frame=''>0 0 10 0 -0 0</pose>
      <diffuse>0.8 0.8 0.8 1</diffuse>
      <specular>0.2 0.2 0.2 1</specular>
      <attenuation>
        <range>1000</range>
        <constant>0.9</constant>
        <linear>0.01</linear>
        <quadratic>0.001</quadratic>
      </attenuation>
      <direction>-0.5 0.1 -0.9</direction>
    </light>
    <plugin name='vrc_plugin' filename='libVRCPlugin.so'>
      <atlas>
        <model_name>atlas</model_name>
        <pin_link>utorso</pin_link>
      </atlas>
      <drc_vehicle>
        <model_name>golf_cart</model_name>
        <seat_link>chassis</seat_link>
      </drc_vehicle>
      <drc_fire_hose>
        <fire_hose_model>fire_hose</fire_hose_model>
        <coupling_link>coupling</coupling_link>
        <standpipe_model>standpipe</standpipe_model>
        <spout_link>standpipe</spout_link>
        <thread_pitch>-1000</thread_pitch>
        <coupling_relative_pose>1.17038e-05 -0.125623 0.35 -0.0412152 -1.57078 1.61199</coupling_relative_pose>
      </drc_fire_hose>
    </plugin>
    <model name='ground_plane'>
      <static>1</static>
      <link name='link'>
        <collision name='collision'>
          <geometry>
            <plane>
              <normal>0 0 1</normal>
              <size>100 100</size>
            </plane>
          </geometry>
          <surface>
            <friction>
              <ode>
                <mu>100</mu>
                <mu2>50</mu2>
              </ode>
            </friction>
            <contact>
              <ode/>
            </contact>
            <bounce/>
          </surface>
          <max_contacts>10</max_contacts>
        </collision>
        <visual name='visual'>
          <cast_shadows>0</cast_shadows>
          <geometry>
            <plane>
              <normal>0 0 1</normal>
              <size>100 100</size>
            </plane>
          </geometry>
          <material>
            <script>
              <uri>file://media/materials/scripts/gazebo.material</uri>
              <name>Gazebo/Grey</name>
            </script>
          </material>
        </visual>
        <self_collide>0</self_collide>
        <kinematic>0</kinematic>
        <gravity>1</gravity>
      </link>
    </model>
    <physics name='default_physics' default='0' type='ode'>
      <max_step_size>0.001</max_step_size>
      <real_time_factor>1</real_time_factor>
      <real_time_update_rate>1000</real_time_update_rate>
      <gravity>0 0 -9.8</gravity>
      <magnetic_field>5.5645e-06 2.28758e-05 -4.23884e-05</magnetic_field>
    </physics>
    <scene>
      <ambient>0.4 0.4 0.4 1</ambient>
      <background>0.7 0.7 0.7 1</background>
      <shadows>1</shadows>
    </scene>
    <spherical_coordinates>
      <surface_model>EARTH_WGS84</surface_model>
      <latitude_deg>0</latitude_deg>
      <longitude_deg>0</longitude_deg>
      <elevation>0</elevation>
      <heading_deg>0</heading_deg>
    </spherical_coordinates>
    <model name='cutout_wall'>
      <static>1</static>
      <link name='link'>
        <pose frame=''>0 0 1.4 0 -0 0</pose>
        <collision name='collision'>
          <geometry>
            <box>
              <size>10 0.2 3.8</size>
            </box>
          </geometry>
          <surface>
            <contact>
              <collide_without_contact>1</collide_without_contact>
              <collide_without_contact_bitmask>2</collide_without_contact_bitmask>
              <ode/>
            </contact>
            <bounce/>
            <friction>
              <ode/>
            </friction>
          </surface>
          <max_contacts>10</max_contacts>
        </collision>
        <visual name='visual'>
          <cast_shadows>0</cast_shadows>
          <geometry>
            <box>
              <size>10 0.2 3.8</size>
            </box>
          </geometry>
          <material>
            <script>
              <uri>model://cutout_wall/materials/scripts</uri>
              <uri>model://cutout_wall/materials/textures</uri>
              <name>drc_practice/cutout_wall</name>
            </script>
          </material>
        </visual>
        <sensor name='mud_contact' type='contact'>
          <always_on>1</always_on>
          <update_rate>1000</update_rate>
          <contact>
            <collision>collision</collision>
            <topic>__default_topic__</topic>
          </contact>
        </sensor>
        <self_collide>0</self_collide>
        <kinematic>0</kinematic>
        <gravity>1</gravity>
      </link>
      <plugin name='gazebo_mud' filename='libMudPlugin.so'>
        <contact_sensor_name>link/mud_contact</contact_sensor_name>
        <stiffness>0.0</stiffness>
        <damping>40.0</damping>
        <contact_surface_bitmask>2</contact_surface_bitmask>
        <link_name>drill::link</link_name>
      </plugin>
      <pose frame=''>3 1 0 0 -0 0</pose>
    </model>
    <model name='cutout_wall_0'>
      <static>1</static>
      <link name='link'>
        <pose frame=''>0 0 1.4 0 -0 0</pose>
        <collision name='collision'>
          <geometry>
            <box>
              <size>10 0.2 3.8</size>
            </box>
          </geometry>
          <surface>
            <contact>
              <collide_without_contact>1</collide_without_contact>
              <collide_without_contact_bitmask>2</collide_without_contact_bitmask>
              <ode/>
            </contact>
            <bounce/>
            <friction>
              <ode/>
            </friction>
          </surface>
          <max_contacts>10</max_contacts>
        </collision>
        <visual name='visual'>
          <cast_shadows>0</cast_shadows>
          <geometry>
            <box>
              <size>10 0.2 3.8</size>
            </box>
          </geometry>
          <material>
            <script>
              <uri>model://cutout_wall/materials/scripts</uri>
              <uri>model://cutout_wall/materials/textures</uri>
              <name>drc_practice/cutout_wall</name>
            </script>
          </material>
        </visual>
        <sensor name='mud_contact' type='contact'>
          <always_on>1</always_on>
          <update_rate>1000</update_rate>
          <contact>
            <collision>collision</collision>
            <topic>__default_topic__</topic>
          </contact>
        </sensor>
        <self_collide>0</self_collide>
        <kinematic>0</kinematic>
        <gravity>1</gravity>
      </link>
      <plugin name='gazebo_mud' filename='libMudPlugin.so'>
        <contact_sensor_name>link/mud_contact</contact_sensor_name>
        <stiffness>0.0</stiffness>
        <damping>40.0</damping>
        <contact_surface_bitmask>2</contact_surface_bitmask>
        <link_name>drill::link</link_name>
      </plugin>
      <pose frame=''>3 -6 0 0 -0 0</pose>
    </model>
    <model name='cutout_wall_1'>
      <static>1</static>
      <link name='link'>
        <pose frame=''>0 0 1.4 0 -0 0</pose>
        <collision name='collision'>
          <geometry>
            <box>
              <size>10 0.2 3.8</size>
            </box>
          </geometry>
          <surface>
            <contact>
              <collide_without_contact>1</collide_without_contact>
              <collide_without_contact_bitmask>2</collide_without_contact_bitmask>
              <ode/>
            </contact>
            <bounce/>
            <friction>
              <ode/>
            </friction>
          </surface>
          <max_contacts>10</max_contacts>
        </collision>
        <visual name='visual'>
          <cast_shadows>0</cast_shadows>
          <geometry>
            <box>
              <size>10 0.2 3.8</size>
            </box>
          </geometry>
          <material>
            <script>
              <uri>model://cutout_wall/materials/scripts</uri>
              <uri>model://cutout_wall/materials/textures</uri>
              <name>drc_practice/cutout_wall</name>
            </script>
          </material>
        </visual>
        <sensor name='mud_contact' type='contact'>
          <always_on>1</always_on>
          <update_rate>1000</update_rate>
          <contact>
            <collision>collision</collision>
            <topic>__default_topic__</topic>
          </contact>
        </sensor>
        <self_collide>0</self_collide>
        <kinematic>0</kinematic>
        <gravity>1</gravity>
      </link>
      <plugin name='gazebo_mud' filename='libMudPlugin.so'>
        <contact_sensor_name>link/mud_contact</contact_sensor_name>
        <stiffness>0.0</stiffness>
        <damping>40.0</damping>
        <contact_surface_bitmask>2</contact_surface_bitmask>
        <link_name>drill::link</link_name>
      </plugin>
      <pose frame=''>6 -4.4729 0 0 -0 0</pose>
    </model>
    <model name='cutout_wall_2'>
      <static>1</static>
      <link name='link'>
        <pose frame=''>0 0 1.4 0 -0 0</pose>
        <collision name='collision'>
          <geometry>
            <box>
              <size>10 0.2 3.8</size>
            </box>
          </geometry>
          <surface>
            <contact>
              <collide_without_contact>1</collide_without_contact>
              <collide_without_contact_bitmask>2</collide_without_contact_bitmask>
              <ode/>
            </contact>
            <bounce/>
            <friction>
              <ode/>
            </friction>
          </surface>
          <max_contacts>10</max_contacts>
        </collision>
        <visual name='visual'>
          <cast_shadows>0</cast_shadows>
          <geometry>
            <box>
              <size>10 0.2 3.8</size>
            </box>
          </geometry>
          <material>
            <script>
              <uri>model://cutout_wall/materials/scripts</uri>
              <uri>model://cutout_wall/materials/textures</uri>
              <name>drc_practice/cutout_wall</name>
            </script>
          </material>
        </visual>
        <sensor name='mud_contact' type='contact'>
          <always_on>1</always_on>
          <update_rate>1000</update_rate>
          <contact>
            <collision>collision</collision>
            <topic>__default_topic__</topic>
          </contact>
        </sensor>
        <self_collide>0</self_collide>
        <kinematic>0</kinematic>
        <gravity>1</gravity>
      </link>
      <plugin name='gazebo_mud' filename='libMudPlugin.so'>
        <contact_sensor_name>link/mud_contact</contact_sensor_name>
        <stiffness>0.0</stiffness>
        <damping>40.0</damping>
        <contact_surface_bitmask>2</contact_surface_bitmask>
        <link_name>drill::link</link_name>
      </plugin>
      <pose frame=''>5 -5 0 0 -0 0</pose>
    </model>
    <state world_name='default'>
      <sim_time>473 163000000</sim_time>
      <real_time>59 668820337</real_time>
      <wall_time>1460134364 861587805</wall_time>
      <model name='atlas'>
        <pose frame=''>0.000656 0.00012 0.910324 -0.001296 -0.008947 0.001798</pose>
        <link name='head'>
          <pose frame=''>0.19931 0.001598 1.58988 -0.002109 -0.619 0.003005</pose>
          <velocity>6.6e-05 0.000148 -6.9e-05 0 0.0112 -0.000133</velocity>
          <acceleration>0.046949 0.043542 -0.218264 -0.000113 -0.008777 0.000831</acceleration>
          <wrench>0.066663 0.061825 -0.309915 0 -0 0</wrench>
        </link>
        <link name='hokuyo_link'>
          <pose frame=''>0.111926 0.001521 1.63567 -0.002671 -0.619002 0.003006</pose>
          <velocity>0.000578 0.000159 0.000911 -0.000359 0.011199 -0.000393</velocity>
          <acceleration>-0.181023 0.047085 -0.165734 -0.003855 -0.00209 -0.002388</acceleration>
          <wrench>-0.010439 0.002715 -0.009557 0 -0 0</wrench>
        </link>
        <link name='l_clav'>
          <pose frame=''>0.008218 0.221828 1.33898 0.015713 0.140702 0.262599</pose>
          <velocity>3.8e-05 0.000175 -6e-06 1.9e-05 4.4e-05 -0.000423</velocity>
          <acceleration>-0.06328 0.008461 0.000601 -2.93772 1.02285 -1.31588</acceleration>
          <wrench>-0.14991 0.020044 0.001425 0 -0 0</wrench>
        </link>
        <link name='l_farm'>
          <pose frame=''>-0.015151 0.393193 0.899903 -1.32189 0.195083 -1.78255</pose>
          <velocity>9.3e-05 0.000196 -1e-06 -8.8e-05 -3.6e-05 0.000211</velocity>
          <acceleration>-0.037025 0.012352 -0.041477 -0.104836 -0.160879 -0.096118</acceleration>
          <wrench>-0.036322 0.012117 -0.040688 0 -0 0</wrench>
        </link>
        <link name='l_foot'>
          <pose frame=''>-0.023106 0.139941 0.081009 -7.7e-05 -9e-06 -0.002609</pose>
          <velocity>-7.7e-05 -2.3e-05 0.00019 0.000327 -0.001288 -2e-06</velocity>
          <acceleration>0.001648 0.002562 -0.007133 0.143531 -0.000512 3.3e-05</acceleration>
          <wrench>0.002692 0.004186 -0.011655 0 -0 0</wrench>
        </link>
        <link name='l_hand'>
          <pose frame=''>0.001108 0.400843 0.844757 -1.32288 0.195083 -1.78255</pose>
          <velocity>9.3e-05 0.000195 -1e-06 -0.000286 -0.000958 2.5e-05</velocity>
          <acceleration>-0.013575 -0.009451 -0.038155 0.044364 0.041569 0.041581</acceleration>
          <wrench>-0.030719 -0.021387 -0.086344 0 -0 0</wrench>
        </link>
        <link name='l_larm'>
          <pose frame=''>-0.055666 0.36514 1.0818 -1.32189 0.195083 -1.78255</pose>
          <velocity>9.2e-05 0.000198 -1e-06 4.1e-05 2.5e-05 -0.000223</velocity>
          <acceleration>0.016559 0.017451 -0.026167 0.207091 0.577291 0.231428</acceleration>
          <wrench>0.035569 0.037484 -0.056207 0 -0 0</wrench>
        </link>
        <link name='l_lglut'>
          <pose frame=''>0.000489 0.08912 0.910234 0.061259 -0.009252 0.00136</pose>
          <velocity>0.000138 3.7e-05 1.9e-05 -4.3e-05 -0.001174 6.8e-05</velocity>
          <acceleration>0.310308 0.002231 0.076415 1.16123 -1.40187 1.99831</acceleration>
          <wrench>0.214112 0.00154 0.052726 0 -0 0</wrench>
        </link>
        <link name='l_lleg'>
          <pose frame=''>0.09151 0.1153 0.486356 0.063648 0.274444 0.019191</pose>
          <velocity>-0.000149 2.5e-05 3.6e-05 -6e-05 7.6e-05 0.000131</velocity>
          <acceleration>-0.114318 0.017478 0.03861 -0.000827 -1.44728 0.096114</acceleration>
          <wrench>-0.499227 0.076328 0.168611 0 -0 0</wrench>
        </link>
        <link name='l_scap'>
          <pose frame=''>-0.006068 0.295055 1.37579 -1.28675 0.140703 0.262598</pose>
          <velocity>7.1e-05 0.00018 -3e-06 -6e-06 3.7e-05 -0.000419</velocity>
          <acceleration>-0.022133 0.018504 -0.012128 -2.44579 -0.447947 1.51062</acceleration>
          <wrench>-0.059913 0.050091 -0.032832 0 -0 0</wrench>
        </link>
        <link name='l_talus'>
          <pose frame=''>-0.023104 0.13994 0.081021 0.061267 -0.000143 -0.00453</pose>
          <velocity>-0.000121 -3e-05 0.000214 -6.6e-05 -0.002086 -1.5e-05</velocity>
          <acceleration>0.028233 0.019241 0.003636 2.83253 -0.955461 -0.288549</acceleration>
          <wrench>0.002823 0.001924 0.000364 0 -0 0</wrench>
        </link>
        <link name='l_uarm'>
          <pose frame=''>-0.043578 0.338659 1.19996 -1.82116 0.195082 -1.78255</pose>
          <velocity>8.6e-05 0.000192 -2e-06 3.4e-05 -6e-06 -0.000229</velocity>
          <acceleration>0.048945 0.019558 -0.021586 -0.31585 -1.50907 -0.894736</acceleration>
          <wrench>0.092066 0.036789 -0.040602 0 -0 0</wrench>
        </link>
        <link name='l_uglut'>
          <pose frame=''>0.000493 0.08912 0.910223 -0.001252 -0.009199 0.001373</pose>
          <velocity>0.000146 3.9e-05 -1e-06 -0.000215 -0.001063 7.1e-05</velocity>
          <acceleration>0.261612 0.000718 0.051698 2.72948 -0.044031 0.680799</acceleration>
          <wrench>0.135149 0.000371 0.026707 0 -0 0</wrench>
        </link>
        <link name='l_uleg'>
          <pose frame=''>0.050939 0.092253 0.860787 0.06308 -0.240286 -0.013102</pose>
          <velocity>0.000186 4e-05 7e-05 -6e-05 0.00089 0.000182</velocity>
          <acceleration>0.030144 0.014434 0.055301 0.002824 -1.35681 -0.018203</acceleration>
          <wrench>0.22126 0.105942 0.405907 0 -0 0</wrench>
        </link>
        <link name='ltorso'>
          <pose frame=''>-0.01184 9.8e-05 0.910207 -0.001301 -0.008904 0.001798</pose>
          <velocity>-9e-06 8.6e-05 -1.2e-05 -0.000382 -0.000562 -0.000493</velocity>
          <acceleration>-0.03024 0.016001 -0.05146 -3.13262 -0.826896 2.97598</acceleration>
          <wrench>-0.058061 0.030723 -0.098802 0 -0 0</wrench>
        </link>
        <link name='mtorso'>
          <pose frame=''>-0.012638 0.000215 1.00018 -0.001736 -0.008125 0.001796</pose>
          <velocity>-6.4e-05 0.000156 -1.6e-05 -0.000803 0.000231 -0.000102</velocity>
          <acceleration>-0.020195 0.021294 -0.007082 2.62485 1.35549 3.13306</acceleration>
          <wrench>-0.011107 0.011712 -0.003895 0 -0 0</wrench>
        </link>
        <link name='pelvis'>
          <pose frame=''>0.000656 0.00012 0.910324 -0.001296 -0.008947 0.001798</pose>
          <velocity>-9e-06 4.2e-05 -1e-06 -0.000274 -0.000588 -0.001824</velocity>
          <acceleration>0.016159 -0.040737 -0.01406 0.005359 -0.008461 0.07085</acceleration>
          <wrench>0.23193 -0.584687 -0.201805 0 -0 0</wrench>
        </link>
        <link name='r_clav'>
          <pose frame=''>0.009006 -0.220171 1.33974 -0.019069 0.139816 -0.259507</pose>
          <velocity>-1.4e-05 0.000175 -2.3e-05 1.4e-05 0.000254 -0.000209</velocity>
          <acceleration>0.056772 0.009618 -0.010793 2.88656 1.02893 1.33003</acceleration>
          <wrench>0.134494 0.022785 -0.025568 0 -0 0</wrench>
        </link>
        <link name='r_farm'>
          <pose frame=''>-0.013747 -0.39311 0.901251 1.32262 0.198409 1.78626</pose>
          <velocity>-0.000119 0.000185 -1e-05 8.3e-05 -4e-06 -0.000375</velocity>
          <acceleration>0.004055 0.007911 0.018317 0.106095 -0.16122 0.100471</acceleration>
          <wrench>0.003978 0.007761 0.017969 0 -0 0</wrench>
        </link>
        <link name='r_foot'>
          <pose frame=''>-0.02121 -0.140018 0.081005 3.2e-05 -6.9e-05 0.003321</pose>
          <velocity>1.6e-05 -3.8e-05 0.000397 0.000447 -0.000425 -2.3e-05</velocity>
          <acceleration>0.004437 -0.000966 0.011991 0.184597 0.002997 4e-05</acceleration>
          <wrench>0.007251 -0.001579 0.019594 0 -0 0</wrench>
        </link>
        <link name='r_hand'>
          <pose frame=''>0.00254 -0.40089 0.846131 1.32361 0.198409 1.78626</pose>
          <velocity>-0.000122 0.000183 -1.1e-05 -0.000114 0.0009 -0.000561</velocity>
          <acceleration>0.002408 0.015004 0.016804 -0.04531 0.041824 -0.044475</acceleration>
          <wrench>0.005449 0.033955 0.038027 0 -0 0</wrench>
        </link>
        <link name='r_larm'>
          <pose frame=''>-0.054365 -0.364584 1.08305 1.32262 0.198409 1.78626</pose>
          <velocity>-0.00011 0.000186 -8e-06 4.1e-05 1.7e-05 -0.000225</velocity>
          <acceleration>-0.013128 -0.006267 0.01476 -0.211872 0.580812 -0.239077</acceleration>
          <wrench>-0.028199 -0.013462 0.031704 0 -0 0</wrench>
        </link>
        <link name='r_lglut'>
          <pose frame=''>0.000817 -0.088872 0.910452 -0.061774 -0.009056 0.002065</pose>
          <velocity>-0.000165 5e-05 3.8e-05 -0.000452 -0.000806 0.000523</velocity>
          <acceleration>-0.111526 0.009152 -0.064408 2.37903 -0.011869 0.742507</acceleration>
          <wrench>-0.076953 0.006315 -0.044442 0 -0 0</wrench>
        </link>
        <link name='r_lleg'>
          <pose frame=''>0.092267 -0.114858 0.486633 -0.063884 0.271857 -0.015678</pose>
          <velocity>0.000348 3.2e-05 0.000159 -0.000121 0.001017 0.000365</velocity>
          <acceleration>0.023935 0.016393 0.012919 -3.1277 -0.734109 3.06169</acceleration>
          <wrench>0.104525 0.071588 0.056418 0 -0 0</wrench>
        </link>
        <link name='r_scap'>
          <pose frame=''>-0.005019 -0.293322 1.3768 1.28344 0.139816 -0.259507</pose>
          <velocity>-2.1e-05 0.000177 -2e-05 1e-05 0.000253 -0.000208</velocity>
          <acceleration>0.027141 0.003232 0.00214 2.48637 -0.452075 -1.53796</acceleration>
          <wrench>0.07347 0.008749 0.005794 0 -0 0</wrench>
        </link>
        <link name='r_talus'>
          <pose frame=''>-0.02123 -0.140023 0.080945 -0.061535 -0.000358 0.000748</pose>
          <velocity>-6.7e-05 -6.1e-05 0.000236 -0.000119 -0.00075 0.000689</velocity>
          <acceleration>0.018569 -0.004114 0.013678 0.277682 0.674313 0.795135</acceleration>
          <wrench>0.001857 -0.000411 0.001368 0 -0 0</wrench>
        </link>
        <link name='r_uarm'>
          <pose frame=''>-0.042372 -0.337658 1.20112 1.82189 0.198408 1.78626</pose>
          <velocity>-7.5e-05 0.000185 -1.1e-05 -8e-06 0.000237 -0.000269</velocity>
          <acceleration>-0.02813 -0.013926 0.014923 0.323169 -1.5154 0.914252</acceleration>
          <wrench>-0.052913 -0.026195 0.02807 0 -0 0</wrench>
        </link>
        <link name='r_uglut'>
          <pose frame=''>0.000814 -0.08888 0.910439 -0.001304 -0.008832 0.002089</pose>
          <velocity>-0.000173 4.2e-05 2.2e-05 -0.000295 -0.000397 0.000525</velocity>
          <acceleration>-0.177301 0.005823 -0.084455 3.10591 0.050607 -2.59511</acceleration>
          <wrench>-0.091594 0.003008 -0.043629 0 -0 0</wrench>
        </link>
        <link name='r_uleg'>
          <pose frame=''>0.051269 -0.091853 0.86102 -0.063372 -0.241211 0.016656</pose>
          <velocity>-0.000126 5.5e-05 0.000105 -0.00012 -0.001233 0.000503</velocity>
          <acceleration>-0.025377 0.035478 0.013275 -3.13876 -1.20249 -3.11431</acceleration>
          <wrench>-0.186269 0.260409 0.097435 0 -0 0</wrench>
        </link>
        <link name='utorso'>
          <pose frame=''>-0.013046 0.000292 1.05018 -0.001721 -0.008094 0.001796</pose>
          <velocity>-4.9e-05 0.000184 -1.1e-05 2.4e-05 0.000212 -0.000118</velocity>
          <acceleration>-0.004675 0.008444 -0.010532 0.016649 0.071411 0.012984</acceleration>
          <wrench>-0.08641 0.156072 -0.194666 0 -0 0</wrench>
        </link>
      </model>
      <model name='cutout_wall'>
        <pose frame=''>3 1 0 0 -0 0</pose>
        <link name='link'>
          <pose frame=''>3 1 1.4 0 -0 0</pose>
          <velocity>0 0 0 0 -0 0</velocity>
          <acceleration>0 0 0 0 -0 0</acceleration>
          <wrench>0 0 0 0 -0 0</wrench>
        </link>
      </model>
      <model name='cutout_wall_0'>
        <pose frame=''>-1.94126 -4.0429 0 0 -0 1.57507</pose>
        <link name='link'>
          <pose frame=''>-1.94126 -4.0429 1.4 0 -0 1.57507</pose>
          <velocity>0 0 0 0 -0 0</velocity>
          <acceleration>0 0 0 0 -0 0</acceleration>
          <wrench>0 0 0 0 -0 0</wrench>
        </link>
      </model>
      <model name='cutout_wall_1'>
        <pose frame=''>2.95415 -9.03799 0 0 -0 0</pose>
        <link name='link'>
          <pose frame=''>2.95415 -9.03799 1.4 0 -0 0</pose>
          <velocity>0 0 0 0 -0 0</velocity>
          <acceleration>0 0 0 0 -0 0</acceleration>
          <wrench>0 0 0 0 -0 0</wrench>
        </link>
      </model>
      <model name='cutout_wall_2'>
        <pose frame=''>7.99859 -4.01588 0 0 0 -1.57885</pose>
        <link name='link'>
          <pose frame=''>7.99859 -4.01588 1.4 0 0 -1.57885</pose>
          <velocity>0 0 0 0 -0 0</velocity>
          <acceleration>0 0 0 0 -0 0</acceleration>
          <wrench>0 0 0 0 -0 0</wrench>
        </link>
      </model>
      <model name='ground_plane'>
        <pose frame=''>0 0 0 0 -0 0</pose>
        <link name='link'>
          <pose frame=''>0 0 0 0 -0 0</pose>
          <velocity>0 0 0 0 -0 0</velocity>
          <acceleration>0 0 0 0 -0 0</acceleration>
          <wrench>0 0 0 0 -0 0</wrench>
        </link>
      </model>
      <iterations>0</iterations>
    </state>
    <gui fullscreen='0'>
      <camera name='user_camera'>
        <pose frame=''>0.019061 -4.06276 10.7397 0 0.981796 0.057826</pose>
        <view_controller>orbit</view_controller>
      </camera>
    </gui>
    <model name='atlas'>
      <link name='pelvis'>
        <pose frame=''>0 0 0 0 -0 0</pose>
        <inertial>
          <pose frame=''>0.0114401 0 0.0268126 0 -0 0</pose>
          <mass>14.3529</mass>
          <inertia>
            <ixx>0.125569</ixx>
            <ixy>0.0008</ixy>
            <ixz>-0.00050004</ixz>
            <iyy>0.0972056</iyy>
            <iyz>-0.0005</iyz>
            <izz>0.117937</izz>
          </inertia>
        </inertial>
        <collision name='pelvis_collision'>
          <pose frame=''>0.046 0 -0.02 1.5708 -0 0</pose>
          <geometry>
            <cylinder>
              <length>0.06</length>
              <radius>0.11</radius>
            </cylinder>
          </geometry>
          <surface>
            <contact>
              <ode/>
            </contact>
            <friction>
              <ode>
                <mu>0.9</mu>
                <mu2>0.9</mu2>
              </ode>
            </friction>
            <bounce/>
          </surface>
          <max_contacts>10</max_contacts>
        </collision>
        <collision name='pelvis_collision_pelvis_1'>
          <pose frame=''>-0.03 0 -0.02 1.5708 -0 0</pose>
          <geometry>
            <cylinder>
              <length>0.06</length>
              <radius>0.11</radius>
            </cylinder>
          </geometry>
          <surface>
            <contact>
              <ode/>
            </contact>
            <friction>
              <ode>
                <mu>0.9</mu>
                <mu2>0.9</mu2>
              </ode>
            </friction>
            <bounce/>
          </surface>
          <max_contacts>10</max_contacts>
        </collision>
        <collision name='pelvis_collision_pelvis_2'>
          <pose frame=''>0.01 0.042 0.09 0 -0 0</pose>
          <geometry>
            <cylinder>
              <length>0.05</length>
              <radius>0.16</radius>
            </cylinder>
          </geometry>
          <surface>
            <contact>
              <ode/>
            </contact>
            <friction>
              <ode>
                <mu>0.9</mu>
                <mu2>0.9</mu2>
              </ode>
            </friction>
            <bounce/>
          </surface>
          <max_contacts>10</max_contacts>
        </collision>
        <collision name='pelvis_collision_pelvis_3'>
          <pose frame=''>0.01 -0.042 0.09 0 -0 0</pose>
          <geometry>
            <cylinder>
              <length>0.05</length>
              <radius>0.16</radius>
            </cylinder>
          </geometry>
          <surface>
            <contact>
              <ode/>
            </contact>
            <friction>
              <ode>
                <mu>0.9</mu>
                <mu2>0.9</mu2>
              </ode>
            </friction>
            <bounce/>
          </surface>
          <max_contacts>10</max_contacts>
        </collision>
        <collision name='pelvis_collision_pelvis_4'>
          <pose frame=''>-0.1 0 -0.05 0 -0 0</pose>
          <geometry>
            <box>
              <size>0.1 0.15 0.2</size>
            </box>
          </geometry>
          <surface>
            <contact>
              <ode/>
            </contact>
            <friction>
              <ode>
                <mu>0.9</mu>
                <mu2>0.9</mu2>
              </ode>
            </friction>
            <bounce/>
          </surface>
          <max_contacts>10</max_contacts>
        </collision>
        <visual name='pelvis_visual'>
          <pose frame=''>0 0 0 0 -0 0</pose>
          <geometry>
            <mesh>
              <scale>1 1 1</scale>
              <uri>model://atlas_description/meshes/pelvis.dae</uri>
            </mesh>
          </geometry>
        </visual>
        <visual name='pelvis_visual_pelvis_1'>
          <pose frame=''>0.0599153 0 -0.01415 0 -0 0</pose>
          <geometry>
            <box>
              <size>0.01 0.01 0.01</size>
            </box>
          </geometry>
        </visual>
        <velocity_decay/>
        <gravity>1</gravity>
        <velocity_decay/>
        <self_collide>0</self_collide>
        <sensor name='imu_sensor' type='imu'>
          <always_on>1</always_on>
          <update_rate>1000</update_rate>
          <imu>
            <noise>
              <type>gaussian</type>
              <rate>
                <mean>0</mean>
                <stddev>0.0002</stddev>
                <bias_mean>7.5e-06</bias_mean>
                <bias_stddev>8e-07</bias_stddev>
              </rate>
              <accel>
                <mean>0</mean>
                <stddev>0.017</stddev>
                <bias_mean>0.1</bias_mean>
                <bias_stddev>0.001</bias_stddev>
              </accel>
            </noise>
          </imu>
          <pose frame=''>0.0599153 0 -0.01415 0 -0 0</pose>
        </sensor>
        <kinematic>0</kinematic>
      </link>
      <link name='ltorso'>
        <pose frame=''>-0.0125 0 0 0 -0 0</pose>
        <inertial>
          <pose frame=''>-0.0112984 -3.15366e-06 0.0746835 0 -0 0</pose>
          <mass>1.92</mass>
          <inertia>
            <ixx>0.0039092</ixx>
            <ixy>-5.04491e-08</ixy>
            <ixz>-0.000342157</ixz>
            <iyy>0.00341694</iyy>
            <iyz>4.87119e-07</iyz>
            <izz>0.00174492</izz>
          </inertia>
        </inertial>
        <visual name='ltorso_visual'>
          <pose frame=''>0 0 0 0 -0 0</pose>
          <geometry>
            <mesh>
              <scale>1 1 1</scale>
              <uri>model://atlas_description/meshes/ltorso.dae</uri>
            </mesh>
          </geometry>
        </visual>
        <gravity>1</gravity>
        <velocity_decay/>
        <self_collide>0</self_collide>
        <kinematic>0</kinematic>
      </link>
      <joint name='back_lbz' type='revolute'>
        <child>ltorso</child>
        <parent>pelvis</parent>
        <axis>
          <xyz>0 0 1</xyz>
          <limit>
            <lower>-0.610865</lower>
            <upper>0.610865</upper>
            <effort>124.016</effort>
            <velocity>12</velocity>
          </limit>
          <dynamics>
            <damping>10</damping>
            <friction>0</friction>
            <spring_reference>0</spring_reference>
            <spring_stiffness>0</spring_stiffness>
          </dynamics>
          <use_parent_model_frame>1</use_parent_model_frame>
        </axis>
        <physics>
          <ode>
            <implicit_spring_damper>1</implicit_spring_damper>
            <cfm_damping>1</cfm_damping>
            <limit>
              <cfm>0</cfm>
              <erp>0.2</erp>
            </limit>
          </ode>
        </physics>
      </joint>
      <link name='mtorso'>
        <pose frame=''>-0.0125 0 0.09 0 -0 0</pose>
        <inertial>
          <pose frame=''>-0.00816266 -0.0131245 0.0305974 0 -0 0</pose>
          <mass>0.55</mass>
          <inertia>
            <ixx>0.000454181</ixx>
            <ixy>-6.10764e-05</ixy>
            <ixz>3.94009e-05</ixz>
            <iyy>0.000483282</iyy>
            <iyz>5.27463e-05</iyz>
            <izz>0.000444215</izz>
          </inertia>
        </inertial>
        <collision name='mtorso_collision'>
          <pose frame=''>0 0 0 1.5708 -0 0</pose>
          <geometry>
            <cylinder>
              <length>0.03</length>
              <radius>0.017</radius>
            </cylinder>
          </geometry>
          <surface>
            <contact>
              <ode/>
            </contact>
            <friction>
              <ode>
                <mu>0.9</mu>
                <mu2>0.9</mu2>
              </ode>
            </friction>
            <bounce/>
          </surface>
          <max_contacts>10</max_contacts>
        </collision>
        <collision name='mtorso_collision_mtorso_1'>
          <pose frame=''>0.0285 0 0.05 -2.65359e-06 1.57079 -2.65359e-06</pose>
          <geometry>
            <cylinder>
              <length>0.02</length>
              <radius>0.015</radius>
            </cylinder>
          </geometry>
          <surface>
            <contact>
              <ode/>
            </contact>
            <friction>
              <ode>
                <mu>0.9</mu>
                <mu2>0.9</mu2>
              </ode>
            </friction>
            <bounce/>
          </surface>
          <max_contacts>10</max_contacts>
        </collision>
        <collision name='mtorso_collision_mtorso_2'>
          <pose frame=''>-0.0285 0 0.05 -2.65359e-06 1.57079 -2.65359e-06</pose>
          <geometry>
            <cylinder>
              <length>0.02</length>
              <radius>0.015</radius>
            </cylinder>
          </geometry>
          <surface>
            <contact>
              <ode/>
            </contact>
            <friction>
              <ode>
                <mu>0.9</mu>
                <mu2>0.9</mu2>
              </ode>
            </friction>
            <bounce/>
          </surface>
          <max_contacts>10</max_contacts>
        </collision>
        <visual name='mtorso_visual'>
          <pose frame=''>0 0 0 0 -0 0</pose>
          <geometry>
            <mesh>
              <scale>1 1 1</scale>
              <uri>model://atlas_description/meshes/mtorso.dae</uri>
            </mesh>
          </geometry>
        </visual>
        <gravity>1</gravity>
        <velocity_decay/>
        <self_collide>0</self_collide>
        <kinematic>0</kinematic>
      </link>
      <joint name='back_mby' type='revolute'>
        <child>mtorso</child>
        <parent>ltorso</parent>
        <axis>
          <xyz>0 1 0</xyz>
          <limit>
            <lower>-1.2</lower>
            <upper>1.28</upper>
            <effort>206.843</effort>
            <velocity>12</velocity>
          </limit>
          <dynamics>
            <damping>10</damping>
            <friction>0</friction>
            <spring_reference>0</spring_reference>
            <spring_stiffness>0</spring_stiffness>
          </dynamics>
          <use_parent_model_frame>1</use_parent_model_frame>
        </axis>
        <physics>
          <ode>
            <implicit_spring_damper>1</implicit_spring_damper>
            <cfm_damping>1</cfm_damping>
            <limit>
              <cfm>0</cfm>
              <erp>0.2</erp>
            </limit>
          </ode>
        </physics>
      </joint>
      <link name='utorso'>
        <pose frame=''>-0.0125 0 0.14 0 -0 0</pose>
        <inertial>
          <pose frame=''>0.02 -0.001 0.211 0 -0 0</pose>
          <mass>18.484</mass>
          <inertia>
            <ixx>0.395</ixx>
            <ixy>0</ixy>
            <ixz>0.083</ixz>
            <iyy>1.089</iyy>
            <iyz>-0.003</iyz>
            <izz>0.827</izz>
          </inertia>
        </inertial>
        <collision name='utorso_collision'>
          <pose frame=''>0.0446 0 0.1869 0 -0 0</pose>
          <geometry>
            <box>
              <size>0.3188 0.24 0.3162</size>
            </box>
          </geometry>
          <surface>
            <contact>
              <ode/>
            </contact>
            <friction>
              <ode>
                <mu>0.9</mu>
                <mu2>0.9</mu2>
              </ode>
            </friction>
            <bounce/>
          </surface>
          <max_contacts>10</max_contacts>
        </collision>
        <collision name='utorso_collision_utorso_1'>
          <pose frame=''>0.024 0.16 0.18 -0.5236 0 0</pose>
          <geometry>
            <cylinder>
              <length>0.22375</length>
              <radius>0.0363</radius>
            </cylinder>
          </geometry>
          <surface>
            <contact>
              <ode/>
            </contact>
            <friction>
              <ode>
                <mu>0.9</mu>
                <mu2>0.9</mu2>
              </ode>
            </friction>
            <bounce/>
          </surface>
          <max_contacts>10</max_contacts>
        </collision>
        <collision name='utorso_collision_utorso_2'>
          <pose frame=''>0.024 -0.16 0.18 0.5236 -0 0</pose>
          <geometry>
            <cylinder>
              <length>0.22375</length>
              <radius>0.0363</radius>
            </cylinder>
          </geometry>
          <surface>
            <contact>
              <ode/>
            </contact>
            <friction>
              <ode>
                <mu>0.9</mu>
                <mu2>0.9</mu2>
              </ode>
            </friction>
            <bounce/>
          </surface>
          <max_contacts>10</max_contacts>
        </collision>
        <visual name='utorso_visual'>
          <pose frame=''>0 0 0 0 -0 0</pose>
          <geometry>
            <mesh>
              <scale>1 1 1</scale>
              <uri>model://atlas_description/meshes/utorso.dae</uri>
            </mesh>
          </geometry>
        </visual>
        <gravity>1</gravity>
        <velocity_decay/>
        <self_collide>0</self_collide>
        <kinematic>0</kinematic>
      </link>
      <joint name='back_ubx' type='revolute'>
        <child>utorso</child>
        <parent>mtorso</parent>
        <axis>
          <xyz>1 0 0</xyz>
          <limit>
            <lower>-0.790809</lower>
            <upper>0.790809</upper>
            <effort>94.91</effort>
            <velocity>12</velocity>
          </limit>
          <dynamics>
            <damping>10</damping>
            <friction>0</friction>
            <spring_reference>0</spring_reference>
            <spring_stiffness>0</spring_stiffness>
          </dynamics>
          <use_parent_model_frame>1</use_parent_model_frame>
        </axis>
        <physics>
          <ode>
            <implicit_spring_damper>1</implicit_spring_damper>
            <cfm_damping>1</cfm_damping>
            <limit>
              <cfm>0</cfm>
              <erp>0.2</erp>
            </limit>
          </ode>
        </physics>
      </joint>
      <link name='l_clav'>
        <pose frame=''>0.0115 0.221 0.429 0 -0 0</pose>
        <inertial>
          <pose frame=''>0.014 0.058 0.029 0 -0 0</pose>
          <mass>2.369</mass>
          <inertia>
            <ixx>0.004</ixx>
            <ixy>0.001</ixy>
            <ixz>0</ixz>
            <iyy>0.006</iyy>
            <iyz>0</iyz>
            <izz>0.007</izz>
          </inertia>
        </inertial>
        <collision name='l_clav_collision'>
          <pose frame=''>0 0.0697 0.0261 -2.65359e-06 1.57079 -2.65359e-06</pose>
          <geometry>
            <cylinder>
              <length>0.1525</length>
              <radius>0.045</radius>
            </cylinder>
          </geometry>
          <surface>
            <contact>
              <ode/>
            </contact>
            <friction>
              <ode>
                <mu>0.9</mu>
                <mu2>0.9</mu2>
              </ode>
            </friction>
            <bounce/>
          </surface>
          <max_contacts>10</max_contacts>
        </collision>
        <collision name='l_clav_collision_l_clav_1'>
          <pose frame=''>-0.005 -0.0074 -0.0538 1.0472 -0 0</pose>
          <geometry>
            <box>
              <size>0.13 0.15 0.05</size>
            </box>
          </geometry>
          <surface>
            <contact>
              <ode/>
            </contact>
            <friction>
              <ode>
                <mu>0.9</mu>
                <mu2>0.9</mu2>
              </ode>
            </friction>
            <bounce/>
          </surface>
          <max_contacts>10</max_contacts>
        </collision>
        <visual name='l_clav_visual'>
          <pose frame=''>0 0 0 1.0472 -0 0</pose>
          <geometry>
            <mesh>
              <scale>1 1 1</scale>
              <uri>model://atlas_description/meshes/l_clav.dae</uri>
            </mesh>
          </geometry>
        </visual>
        <gravity>1</gravity>
        <velocity_decay/>
        <self_collide>0</self_collide>
        <kinematic>0</kinematic>
      </link>
      <joint name='l_arm_usy' type='revolute'>
        <child>l_clav</child>
        <parent>utorso</parent>
        <axis>
          <xyz>0 0.5 0.866025</xyz>
          <limit>
            <lower>-1.9635</lower>
            <upper>1.9635</upper>
            <effort>212</effort>
            <velocity>12</velocity>
          </limit>
          <dynamics>
            <damping>1</damping>
            <friction>0</friction>
            <spring_reference>0</spring_reference>
            <spring_stiffness>0</spring_stiffness>
          </dynamics>
          <use_parent_model_frame>1</use_parent_model_frame>
        </axis>
        <physics>
          <ode>
            <implicit_spring_damper>1</implicit_spring_damper>
            <cfm_damping>1</cfm_damping>
            <limit>
              <cfm>0</cfm>
              <erp>0.2</erp>
            </limit>
          </ode>
        </physics>
      </joint>
      <link name='l_scap'>
        <pose frame=''>0.0115 0.296 0.465 0 -0 0</pose>
        <inertial>
          <pose frame=''>-0.002 0.108 0 0 -0 0</pose>
          <mass>2.707</mass>
          <inertia>
            <ixx>0.01</ixx>
            <ixy>0</ixy>
            <ixz>0</ixz>
            <iyy>0.005</iyy>
            <iyz>0</iyz>
            <izz>0.013</izz>
          </inertia>
        </inertial>
        <collision name='l_scap_collision'>
          <pose frame=''>0.001 0.12651 0.01521 1.5708 -0 0</pose>
          <geometry>
            <cylinder>
              <length>0.125</length>
              <radius>0.045</radius>
            </cylinder>
          </geometry>
          <surface>
            <contact>
              <ode/>
            </contact>
            <friction>
              <ode>
                <mu>0.9</mu>
                <mu2>0.9</mu2>
              </ode>
            </friction>
            <bounce/>
          </surface>
          <max_contacts>10</max_contacts>
        </collision>
        <collision name='l_scap_collision_l_scap_1'>
          <pose frame=''>0.001 0.05 0.016 0 -0 0</pose>
          <geometry>
            <box>
              <size>0.15 0.15 0.06</size>
            </box>
          </geometry>
          <surface>
            <contact>
              <ode/>
            </contact>
            <friction>
              <ode>
                <mu>0.9</mu>
                <mu2>0.9</mu2>
              </ode>
            </friction>
            <bounce/>
          </surface>
          <max_contacts>10</max_contacts>
        </collision>
        <visual name='l_scap_visual'>
          <pose frame=''>0 0 0 0 -0 0</pose>
          <geometry>
            <mesh>
              <scale>1 1 1</scale>
              <uri>model://atlas_description/meshes/l_scap.dae</uri>
            </mesh>
          </geometry>
        </visual>
        <gravity>1</gravity>
        <velocity_decay/>
        <self_collide>0</self_collide>
        <kinematic>0</kinematic>
      </link>
      <joint name='l_arm_shx' type='revolute'>
        <child>l_scap</child>
        <parent>l_clav</parent>
        <axis>
          <xyz>1 0 0</xyz>
          <limit>
            <lower>-1.39626</lower>
            <upper>1.74533</upper>
            <effort>170</effort>
            <velocity>12</velocity>
          </limit>
          <dynamics>
            <damping>1</damping>
            <friction>0</friction>
            <spring_reference>0</spring_reference>
            <spring_stiffness>0</spring_stiffness>
          </dynamics>
          <use_parent_model_frame>1</use_parent_model_frame>
        </axis>
        <physics>
          <ode>
            <implicit_spring_damper>1</implicit_spring_damper>
            <cfm_damping>1</cfm_damping>
            <limit>
              <cfm>0</cfm>
              <erp>0.2</erp>
            </limit>
          </ode>
        </physics>
      </joint>
      <link name='l_uarm'>
        <pose frame=''>0.0115 0.481 0.465 0 -0 0</pose>
        <inertial>
          <pose frame=''>0.007 0.114 0.008 0 -0 0</pose>
          <mass>1.881</mass>
          <inertia>
            <ixx>0.002</ixx>
            <ixy>0</ixy>
            <ixz>0</ixz>
            <iyy>0.003</iyy>
            <iyz>0</iyz>
            <izz>0.003</izz>
          </inertia>
        </inertial>
        <collision name='l_uarm_collision'>
          <pose frame=''>0.001 0.111 0 3.14159 1.57079 3.14159</pose>
          <geometry>
            <cylinder>
              <length>0.125</length>
              <radius>0.045</radius>
            </cylinder>
          </geometry>
          <surface>
            <contact>
              <ode/>
            </contact>
            <friction>
              <ode>
                <mu>0.9</mu>
                <mu2>0.9</mu2>
              </ode>
            </friction>
            <bounce/>
          </surface>
          <max_contacts>10</max_contacts>
        </collision>
        <collision name='l_uarm_collision_l_uarm_1'>
          <pose frame=''>0.001 0.043 0.01 -2.65359e-06 1.57079 -2.65359e-06</pose>
          <geometry>
            <box>
              <size>0.04 0.07 0.13</size>
            </box>
          </geometry>
          <surface>
            <contact>
              <ode/>
            </contact>
            <friction>
              <ode>
                <mu>0.9</mu>
                <mu2>0.9</mu2>
              </ode>
            </friction>
            <bounce/>
          </surface>
          <max_contacts>10</max_contacts>
        </collision>
        <visual name='l_uarm_visual'>
          <pose frame=''>0 0 0 0 -0 0</pose>
          <geometry>
            <mesh>
              <scale>1 1 1</scale>
              <uri>model://atlas_description/meshes/l_uarm.dae</uri>
            </mesh>
          </geometry>
        </visual>
        <gravity>1</gravity>
        <velocity_decay/>
        <self_collide>0</self_collide>
        <kinematic>0</kinematic>
      </link>
      <joint name='l_arm_ely' type='revolute'>
        <child>l_uarm</child>
        <parent>l_scap</parent>
        <axis>
          <xyz>0 1 0</xyz>
          <limit>
            <lower>0</lower>
            <upper>3.14159</upper>
            <effort>114</effort>
            <velocity>12</velocity>
          </limit>
          <dynamics>
            <damping>1</damping>
            <friction>0</friction>
            <spring_reference>0</spring_reference>
            <spring_stiffness>0</spring_stiffness>
          </dynamics>
          <use_parent_model_frame>1</use_parent_model_frame>
        </axis>
        <physics>
          <ode>
            <implicit_spring_damper>1</implicit_spring_damper>
            <cfm_damping>1</cfm_damping>
            <limit>
              <cfm>0</cfm>
              <erp>0.2</erp>
            </limit>
          </ode>
        </physics>
      </joint>
      <link name='l_larm'>
        <pose frame=''>0.0115 0.602 0.478 0 -0 0</pose>
        <inertial>
          <pose frame=''>-0.003 0.099 -0.014 0 -0 0</pose>
          <mass>2.148</mass>
          <inertia>
            <ixx>0.005</ixx>
            <ixy>0</ixy>
            <ixz>0</ixz>
            <iyy>0.003</iyy>
            <iyz>0</iyz>
            <izz>0.006</izz>
          </inertia>
        </inertial>
        <collision name='l_larm_collision'>
          <pose frame=''>0.001 0.127 0 1.5708 -0 0</pose>
          <geometry>
            <cylinder>
              <length>0.125</length>
              <radius>0.045</radius>
            </cylinder>
          </geometry>
          <surface>
            <contact>
              <ode/>
            </contact>
            <friction>
              <ode>
                <mu>0.9</mu>
                <mu2>0.9</mu2>
              </ode>
            </friction>
            <bounce/>
          </surface>
          <max_contacts>10</max_contacts>
        </collision>
        <collision name='l_larm_collision_l_larm_1'>
          <pose frame=''>0.001 0.051 0 0 -0 0</pose>
          <geometry>
            <box>
              <size>0.135 0.15 0.06</size>
            </box>
          </geometry>
          <surface>
            <contact>
              <ode/>
            </contact>
            <friction>
              <ode>
                <mu>0.9</mu>
                <mu2>0.9</mu2>
              </ode>
            </friction>
            <bounce/>
          </surface>
          <max_contacts>10</max_contacts>
        </collision>
        <visual name='l_larm_visual'>
          <pose frame=''>0 0 0 0 -0 0</pose>
          <geometry>
            <mesh>
              <scale>1 1 1</scale>
              <uri>model://atlas_description/meshes/l_larm.dae</uri>
            </mesh>
          </geometry>
        </visual>
        <gravity>1</gravity>
        <velocity_decay/>
        <self_collide>0</self_collide>
        <kinematic>0</kinematic>
      </link>
      <joint name='l_arm_elx' type='revolute'>
        <child>l_larm</child>
        <parent>l_uarm</parent>
        <axis>
          <xyz>1 0 0</xyz>
          <limit>
            <lower>0</lower>
            <upper>2.35619</upper>
            <effort>114</effort>
            <velocity>12</velocity>
          </limit>
          <dynamics>
            <damping>1</damping>
            <friction>0</friction>
            <spring_reference>0</spring_reference>
            <spring_stiffness>0</spring_stiffness>
          </dynamics>
          <use_parent_model_frame>1</use_parent_model_frame>
        </axis>
        <physics>
          <ode>
            <implicit_spring_damper>1</implicit_spring_damper>
            <cfm_damping>1</cfm_damping>
            <limit>
              <cfm>0</cfm>
              <erp>0.2</erp>
            </limit>
          </ode>
        </physics>
      </joint>
      <link name='l_farm'>
        <pose frame=''>0.0115 0.79 0.465 0 -0 0</pose>
        <inertial>
          <pose frame=''>0 0.041 0 0 -0 0</pose>
          <mass>0.981</mass>
          <inertia>
            <ixx>0.003</ixx>
            <ixy>0</ixy>
            <ixz>0</ixz>
            <iyy>0.001</iyy>
            <iyz>0</iyz>
            <izz>0.003</izz>
          </inertia>
        </inertial>
        <collision name='l_farm_collision'>
          <pose frame=''>0 0.065 0.004 3.14159 1.57079 3.14159</pose>
          <geometry>
            <cylinder>
              <length>0.125</length>
              <radius>0.045</radius>
            </cylinder>
          </geometry>
          <surface>
            <contact>
              <ode/>
            </contact>
            <friction>
              <ode>
                <mu>0.9</mu>
                <mu2>0.9</mu2>
              </ode>
            </friction>
            <bounce/>
          </surface>
          <max_contacts>10</max_contacts>
        </collision>
        <collision name='l_farm_collision_l_farm_1'>
          <pose frame=''>0.001 0.015 -0.002 0 -0 0</pose>
          <geometry>
            <box>
              <size>0.135 0.1 0.045</size>
            </box>
          </geometry>
          <surface>
            <contact>
              <ode/>
            </contact>
            <friction>
              <ode>
                <mu>0.9</mu>
                <mu2>0.9</mu2>
              </ode>
            </friction>
            <bounce/>
          </surface>
          <max_contacts>10</max_contacts>
        </collision>
        <visual name='l_farm_visual'>
          <pose frame=''>0 -0.06 0 0 -0 0</pose>
          <geometry>
            <mesh>
              <scale>1 1 1</scale>
              <uri>model://atlas_description/meshes/l_farm.dae</uri>
            </mesh>
          </geometry>
        </visual>
        <gravity>1</gravity>
        <velocity_decay/>
        <self_collide>0</self_collide>
        <kinematic>0</kinematic>
      </link>
      <joint name='l_arm_uwy' type='revolute'>
        <child>l_farm</child>
        <parent>l_larm</parent>
        <axis>
          <xyz>0 1 0</xyz>
          <limit>
            <lower>-1.571</lower>
            <upper>1.571</upper>
            <effort>114</effort>
            <velocity>12</velocity>
          </limit>
          <dynamics>
            <damping>1</damping>
            <friction>0</friction>
            <spring_reference>0</spring_reference>
            <spring_stiffness>0</spring_stiffness>
          </dynamics>
          <use_parent_model_frame>1</use_parent_model_frame>
        </axis>
        <physics>
          <ode>
            <implicit_spring_damper>1</implicit_spring_damper>
            <cfm_damping>1</cfm_damping>
            <limit>
              <cfm>0</cfm>
              <erp>0.2</erp>
            </limit>
          </ode>
        </physics>
      </joint>
      <link name='l_hand'>
        <pose frame=''>0.0115 0.848 0.465 0 -0 0</pose>
        <inertial>
          <pose frame=''>0 0.093 0 0 -0 0</pose>
          <mass>2.263</mass>
          <inertia>
            <ixx>0.01</ixx>
            <ixy>0</ixy>
            <ixz>0</ixz>
            <iyy>0.002</iyy>
            <iyz>0</iyz>
            <izz>0.01</izz>
          </inertia>
        </inertial>
        <collision name='l_hand_collision'>
          <pose frame=''>0.001 0.1 0.01 1.5708 -0 0</pose>
          <geometry>
            <cylinder>
              <length>0.05</length>
              <radius>0.03</radius>
            </cylinder>
          </geometry>
          <surface>
            <contact>
              <ode/>
            </contact>
            <friction>
              <ode>
                <mu>0.9</mu>
                <mu2>0.9</mu2>
              </ode>
            </friction>
            <bounce/>
          </surface>
          <max_contacts>10</max_contacts>
        </collision>
        <collision name='l_hand_collision_l_hand_1'>
          <pose frame=''>0.001 0.05 0.01 0 -0 0</pose>
          <geometry>
            <box>
              <size>0.13 0.09 0.07</size>
            </box>
          </geometry>
          <surface>
            <contact>
              <ode/>
            </contact>
            <friction>
              <ode>
                <mu>0.9</mu>
                <mu2>0.9</mu2>
              </ode>
            </friction>
            <bounce/>
          </surface>
          <max_contacts>10</max_contacts>
        </collision>
        <visual name='l_hand_visual'>
          <pose frame=''>0 0 0 0 -0 0</pose>
          <geometry>
            <mesh>
              <scale>1 1 1</scale>
              <uri>model://atlas_description/meshes/l_hand.dae</uri>
            </mesh>
          </geometry>
        </visual>
        <gravity>1</gravity>
        <velocity_decay/>
        <self_collide>0</self_collide>
        <kinematic>0</kinematic>
      </link>
      <joint name='l_arm_mwx' type='revolute'>
        <child>l_hand</child>
        <parent>l_farm</parent>
        <axis>
          <xyz>1 0 0</xyz>
          <limit>
            <lower>-0.436</lower>
            <upper>1.571</upper>
            <effort>60</effort>
            <velocity>12</velocity>
          </limit>
          <dynamics>
            <damping>1</damping>
            <friction>0</friction>
            <spring_reference>0</spring_reference>
            <spring_stiffness>0</spring_stiffness>
          </dynamics>
          <use_parent_model_frame>1</use_parent_model_frame>
        </axis>
        <physics>
          <provide_feedback>1</provide_feedback>
          <ode>
            <provide_feedback>1</provide_feedback>
            <limit>
              <cfm>0</cfm>
              <erp>0.2</erp>
            </limit>
            <implicit_spring_damper>1</implicit_spring_damper>
            <cfm_damping>1</cfm_damping>
          </ode>
        </physics>
      </joint>
      <link name='head'>
        <pose frame=''>0.20422 0 0.67796 0 -0 0</pose>
        <inertial>
          <pose frame=''>-0.0754942 3.38765e-05 0.0277411 0 -0 0</pose>
          <mass>1.41991</mass>
          <inertia>
            <ixx>0.00397627</ixx>
            <ixy>-1.51324e-06</ixy>
            <ixz>-0.000892818</ixz>
            <iyy>0.00412515</iyy>
            <iyz>-6.83342e-07</iyz>
            <izz>0.00353178</izz>
          </inertia>
        </inertial>
        <collision name='head_collision'>
          <pose frame=''>-0.0503 0 -0.00195 0 -0 0</pose>
          <geometry>
            <box>
              <size>0.1311 0.12 0.0591</size>
            </box>
          </geometry>
          <surface>
            <contact>
              <ode/>
            </contact>
            <friction>
              <ode>
                <mu>0.9</mu>
                <mu2>0.9</mu2>
              </ode>
            </friction>
            <bounce/>
          </surface>
          <max_contacts>10</max_contacts>
        </collision>
        <collision name='head_collision_head_1'>
          <pose frame=''>-0.093 0 0.0868 0 -0 0</pose>
          <geometry>
            <box>
              <size>0.0468 0.12 0.1184</size>
            </box>
          </geometry>
          <surface>
            <contact>
              <ode/>
            </contact>
            <friction>
              <ode>
                <mu>0.9</mu>
                <mu2>0.9</mu2>
              </ode>
            </friction>
            <bounce/>
          </surface>
          <max_contacts>10</max_contacts>
        </collision>
        <visual name='head_visual'>
          <pose frame=''>0 0 0 0 -0 0</pose>
          <geometry>
            <mesh>
              <scale>1 1 1</scale>
              <uri>model://multisense_sl_description/meshes/head.dae</uri>
            </mesh>
          </geometry>
        </visual>
        <visual name='head_visual_head_1'>
          <pose frame=''>-0.0475 0.035 0 0 -0 0</pose>
          <geometry>
            <box>
              <size>0.01 0.01 0.01</size>
            </box>
          </geometry>
        </visual>
        <velocity_decay/>
        <velocity_decay/>
        <sensor name='head_imu_sensor' type='imu'>
          <always_on>1</always_on>
          <update_rate>1000</update_rate>
          <imu>
            <noise>
              <type>gaussian</type>
              <rate>
                <mean>0</mean>
                <stddev>0.0002</stddev>
                <bias_mean>7.5e-06</bias_mean>
                <bias_stddev>8e-07</bias_stddev>
              </rate>
              <accel>
                <mean>0</mean>
                <stddev>0.017</stddev>
                <bias_mean>0.1</bias_mean>
                <bias_stddev>0.001</bias_stddev>
              </accel>
            </noise>
          </imu>
          <pose frame=''>-0.0475 0.035 0 0 -0 0</pose>
        </sensor>
        <gravity>1</gravity>
        <velocity_decay/>
        <self_collide>0</self_collide>
        <sensor name='stereo_camera' type='multicamera'>
          <update_rate>30</update_rate>
          <camera name='left'>
            <horizontal_fov>1.39626</horizontal_fov>
            <image>
              <width>800</width>
              <height>800</height>
              <format>R8G8B8</format>
            </image>
            <clip>
              <near>0.02</near>
              <far>300</far>
            </clip>
            <noise>
              <type>gaussian</type>
              <mean>0</mean>
              <stddev>0.007</stddev>
            </noise>
          </camera>
          <camera name='right'>
            <pose frame=''>0 -0.07 0 0 -0 0</pose>
            <horizontal_fov>1.39626</horizontal_fov>
            <image>
              <width>800</width>
              <height>800</height>
              <format>R8G8B8</format>
            </image>
            <clip>
              <near>0.02</near>
              <far>300</far>
            </clip>
            <noise>
              <type>gaussian</type>
              <mean>0</mean>
              <stddev>0.007</stddev>
            </noise>
          </camera>
          <plugin name='stereo_camera_controller' filename='libgazebo_ros_multicamera.so'>
            <alwaysOn>true</alwaysOn>
            <updateRate>0.0</updateRate>
            <cameraName>multisense_sl</cameraName>
            <imageTopicName>image_raw</imageTopicName>
            <cameraInfoTopicName>camera_info</cameraInfoTopicName>
            <frameName>left_camera_optical_frame</frameName>
            <hackBaseline>0.07</hackBaseline>
            <distortionK1>0.0</distortionK1>
            <distortionK2>0.0</distortionK2>
            <distortionK3>0.0</distortionK3>
            <distortionT1>0.0</distortionT1>
            <distortionT2>0.0</distortionT2>
          </plugin>
          <pose frame=''>0 0.035 -0.002 0 -0 0</pose>
        </sensor>
        <kinematic>0</kinematic>
      </link>
      <joint name='neck_ay' type='revolute'>
        <child>head</child>
        <parent>utorso</parent>
        <axis>
          <xyz>0 1 0</xyz>
          <limit>
            <lower>-0.610865</lower>
            <upper>1.13446</upper>
            <effort>5</effort>
            <velocity>12</velocity>
          </limit>
          <dynamics>
            <damping>1</damping>
            <friction>0</friction>
            <spring_reference>0</spring_reference>
            <spring_stiffness>0</spring_stiffness>
          </dynamics>
          <use_parent_model_frame>1</use_parent_model_frame>
        </axis>
        <physics>
          <ode>
            <implicit_spring_damper>1</implicit_spring_damper>
            <cfm_damping>1</cfm_damping>
            <limit>
              <cfm>0</cfm>
              <erp>0.2</erp>
            </limit>
          </ode>
        </physics>
      </joint>
      <link name='hokuyo_link'>
        <pose frame=''>0.15962 0 0.76596 0 -0 0</pose>
        <inertial>
          <pose frame=''>0.0324349 0.0004084 -0.0041783 0 -0 0</pose>
          <mass>0.057664</mass>
          <inertia>
            <ixx>3.8183e-05</ixx>
            <ixy>4.9927e-08</ixy>
            <ixz>1.1003e-05</ixz>
            <iyy>4.3437e-05</iyy>
            <iyz>-9.8165e-09</iyz>
            <izz>4.2686e-05</izz>
          </inertia>
        </inertial>
        <collision name='hokuyo_link_collision'>
          <pose frame=''>0.01885 0 -0.02119 0 -0 0</pose>
          <geometry>
            <box>
              <size>0.08 0.06 0.04238</size>
            </box>
          </geometry>
          <surface>
            <contact>
              <ode/>
            </contact>
            <friction>
              <ode>
                <mu>0.9</mu>
                <mu2>0.9</mu2>
              </ode>
            </friction>
            <bounce/>
          </surface>
          <max_contacts>10</max_contacts>
        </collision>
        <collision name='hokuyo_link_collision_hokuyo_link_1'>
          <pose frame=''>0.03 0 0.0235 0 -0 0</pose>
          <geometry>
            <cylinder>
              <length>0.047</length>
              <radius>0.024425</radius>
            </cylinder>
          </geometry>
          <surface>
            <contact>
              <ode/>
            </contact>
            <friction>
              <ode>
                <mu>0.9</mu>
                <mu2>0.9</mu2>
              </ode>
            </friction>
            <bounce/>
          </surface>
          <max_contacts>10</max_contacts>
        </collision>
        <visual name='hokuyo_link_visual'>
          <pose frame=''>0.045 -0.0261018 -0.0834237 -0.314 0 0</pose>
          <geometry>
            <mesh>
              <scale>1 1 1</scale>
              <uri>model://multisense_sl_description/meshes/head_camera.dae</uri>
            </mesh>
          </geometry>
        </visual>
        <velocity_decay/>
        <gravity>1</gravity>
        <velocity_decay/>
        <self_collide>0</self_collide>
        <sensor name='head_hokuyo_sensor' type='gpu_ray'>
          <visualize>0</visualize>
          <update_rate>40</update_rate>
          <ray>
            <scan>
              <horizontal>
                <samples>720</samples>
                <resolution>1</resolution>
                <min_angle>-1.5708</min_angle>
                <max_angle>1.5708</max_angle>
              </horizontal>
            </scan>
            <range>
              <min>0.1</min>
              <max>30</max>
              <resolution>0.01</resolution>
            </range>
            <noise>
              <type>gaussian</type>
              <mean>0</mean>
              <stddev>0.01</stddev>
            </noise>
          </ray>
          <plugin name='gazebo_ros_head_hokuyo_controller' filename='libgazebo_ros_gpu_laser.so'>
            <topicName>/laser/scan</topicName>
            <frameName>head_hokuyo_frame</frameName>
          </plugin>
          <pose frame=''>0.03 0 0.015 0 -0 0</pose>
        </sensor>
        <kinematic>0</kinematic>
      </link>
      <joint name='hokuyo_joint' type='revolute'>
        <child>hokuyo_link</child>
        <parent>head</parent>
        <axis>
          <xyz>1 0 0</xyz>
          <limit>
            <lower>-1e+16</lower>
            <upper>1e+16</upper>
          </limit>
          <dynamics>
            <damping>0.01</damping>
            <friction>0</friction>
            <spring_reference>0</spring_reference>
            <spring_stiffness>0</spring_stiffness>
          </dynamics>
          <use_parent_model_frame>1</use_parent_model_frame>
        </axis>
        <physics>
          <ode>
            <implicit_spring_damper>1</implicit_spring_damper>
            <cfm_damping>1</cfm_damping>
            <limit>
              <cfm>0</cfm>
              <erp>0.2</erp>
            </limit>
          </ode>
        </physics>
      </joint>
      <link name='r_clav'>
        <pose frame=''>0.0115 -0.221 0.429 0 -0 0</pose>
        <inertial>
          <pose frame=''>0.014 -0.058 0.029 0 -0 0</pose>
          <mass>2.369</mass>
          <inertia>
            <ixx>0.004</ixx>
            <ixy>-0.001</ixy>
            <ixz>0</ixz>
            <iyy>0.006</iyy>
            <iyz>0</iyz>
            <izz>0.007</izz>
          </inertia>
        </inertial>
        <collision name='r_clav_collision'>
          <pose frame=''>0 -0.0697 0.0261 -2.65359e-06 1.57079 -2.65359e-06</pose>
          <geometry>
            <cylinder>
              <length>0.1525</length>
              <radius>0.045</radius>
            </cylinder>
          </geometry>
          <surface>
            <contact>
              <ode/>
            </contact>
            <friction>
              <ode>
                <mu>0.9</mu>
                <mu2>0.9</mu2>
              </ode>
            </friction>
            <bounce/>
          </surface>
          <max_contacts>10</max_contacts>
        </collision>
        <collision name='r_clav_collision_r_clav_1'>
          <pose frame=''>-0.005 0.0074 -0.0538 -1.0472 0 0</pose>
          <geometry>
            <box>
              <size>0.13 0.15 0.05</size>
            </box>
          </geometry>
          <surface>
            <contact>
              <ode/>
            </contact>
            <friction>
              <ode>
                <mu>0.9</mu>
                <mu2>0.9</mu2>
              </ode>
            </friction>
            <bounce/>
          </surface>
          <max_contacts>10</max_contacts>
        </collision>
        <visual name='r_clav_visual'>
          <pose frame=''>0 0 0 -1.0472 0 0</pose>
          <geometry>
            <mesh>
              <scale>1 1 1</scale>
              <uri>model://atlas_description/meshes/r_clav.dae</uri>
            </mesh>
          </geometry>
        </visual>
        <gravity>1</gravity>
        <velocity_decay/>
        <self_collide>0</self_collide>
        <kinematic>0</kinematic>
      </link>
      <joint name='r_arm_usy' type='revolute'>
        <child>r_clav</child>
        <parent>utorso</parent>
        <axis>
          <xyz>0 0.5 -0.866025</xyz>
          <limit>
            <lower>-1.9635</lower>
            <upper>1.9635</upper>
            <effort>212</effort>
            <velocity>12</velocity>
          </limit>
          <dynamics>
            <damping>1</damping>
            <friction>0</friction>
            <spring_reference>0</spring_reference>
            <spring_stiffness>0</spring_stiffness>
          </dynamics>
          <use_parent_model_frame>1</use_parent_model_frame>
        </axis>
        <physics>
          <ode>
            <implicit_spring_damper>1</implicit_spring_damper>
            <cfm_damping>1</cfm_damping>
            <limit>
              <cfm>0</cfm>
              <erp>0.2</erp>
            </limit>
          </ode>
        </physics>
      </joint>
      <link name='r_scap'>
        <pose frame=''>0.0115 -0.296 0.465 0 -0 0</pose>
        <inertial>
          <pose frame=''>-0.002 -0.108 0 0 -0 0</pose>
          <mass>2.707</mass>
          <inertia>
            <ixx>0.01</ixx>
            <ixy>0</ixy>
            <ixz>0</ixz>
            <iyy>0.005</iyy>
            <iyz>0</iyz>
            <izz>0.013</izz>
          </inertia>
        </inertial>
        <collision name='r_scap_collision'>
          <pose frame=''>0.001 -0.12651 0.01521 1.5708 -0 0</pose>
          <geometry>
            <cylinder>
              <length>0.125</length>
              <radius>0.045</radius>
            </cylinder>
          </geometry>
          <surface>
            <contact>
              <ode/>
            </contact>
            <friction>
              <ode>
                <mu>0.9</mu>
                <mu2>0.9</mu2>
              </ode>
            </friction>
            <bounce/>
          </surface>
          <max_contacts>10</max_contacts>
        </collision>
        <collision name='r_scap_collision_r_scap_1'>
          <pose frame=''>0.001 -0.05 0.016 0 -0 0</pose>
          <geometry>
            <box>
              <size>0.15 0.15 0.06</size>
            </box>
          </geometry>
          <surface>
            <contact>
              <ode/>
            </contact>
            <friction>
              <ode>
                <mu>0.9</mu>
                <mu2>0.9</mu2>
              </ode>
            </friction>
            <bounce/>
          </surface>
          <max_contacts>10</max_contacts>
        </collision>
        <visual name='r_scap_visual'>
          <pose frame=''>0 0 0 0 -0 0</pose>
          <geometry>
            <mesh>
              <scale>1 1 1</scale>
              <uri>model://atlas_description/meshes/r_scap.dae</uri>
            </mesh>
          </geometry>
        </visual>
        <gravity>1</gravity>
        <velocity_decay/>
        <self_collide>0</self_collide>
        <kinematic>0</kinematic>
      </link>
      <joint name='r_arm_shx' type='revolute'>
        <child>r_scap</child>
        <parent>r_clav</parent>
        <axis>
          <xyz>1 0 0</xyz>
          <limit>
            <lower>-1.74533</lower>
            <upper>1.39626</upper>
            <effort>170</effort>
            <velocity>12</velocity>
          </limit>
          <dynamics>
            <damping>1</damping>
            <friction>0</friction>
            <spring_reference>0</spring_reference>
            <spring_stiffness>0</spring_stiffness>
          </dynamics>
          <use_parent_model_frame>1</use_parent_model_frame>
        </axis>
        <physics>
          <ode>
            <implicit_spring_damper>1</implicit_spring_damper>
            <cfm_damping>1</cfm_damping>
            <limit>
              <cfm>0</cfm>
              <erp>0.2</erp>
            </limit>
          </ode>
        </physics>
      </joint>
      <link name='r_uarm'>
        <pose frame=''>0.0115 -0.481 0.465 0 -0 0</pose>
        <inertial>
          <pose frame=''>0.007 -0.114 0.008 0 -0 0</pose>
          <mass>1.881</mass>
          <inertia>
            <ixx>0.002</ixx>
            <ixy>0</ixy>
            <ixz>0</ixz>
            <iyy>0.003</iyy>
            <iyz>0</iyz>
            <izz>0.003</izz>
          </inertia>
        </inertial>
        <collision name='r_uarm_collision'>
          <pose frame=''>0.001 -0.111 0 3.14159 1.57079 3.14159</pose>
          <geometry>
            <cylinder>
              <length>0.125</length>
              <radius>0.045</radius>
            </cylinder>
          </geometry>
          <surface>
            <contact>
              <ode/>
            </contact>
            <friction>
              <ode>
                <mu>0.9</mu>
                <mu2>0.9</mu2>
              </ode>
            </friction>
            <bounce/>
          </surface>
          <max_contacts>10</max_contacts>
        </collision>
        <collision name='r_uarm_collision_r_uarm_1'>
          <pose frame=''>0.001 -0.043 0.01 -2.65359e-06 1.57079 -2.65359e-06</pose>
          <geometry>
            <box>
              <size>0.04 0.07 0.13</size>
            </box>
          </geometry>
          <surface>
            <contact>
              <ode/>
            </contact>
            <friction>
              <ode>
                <mu>0.9</mu>
                <mu2>0.9</mu2>
              </ode>
            </friction>
            <bounce/>
          </surface>
          <max_contacts>10</max_contacts>
        </collision>
        <visual name='r_uarm_visual'>
          <pose frame=''>0 0 0 0 -0 0</pose>
          <geometry>
            <mesh>
              <scale>1 1 1</scale>
              <uri>model://atlas_description/meshes/r_uarm.dae</uri>
            </mesh>
          </geometry>
        </visual>
        <gravity>1</gravity>
        <velocity_decay/>
        <self_collide>0</self_collide>
        <kinematic>0</kinematic>
      </link>
      <joint name='r_arm_ely' type='revolute'>
        <child>r_uarm</child>
        <parent>r_scap</parent>
        <axis>
          <xyz>0 1 0</xyz>
          <limit>
            <lower>0</lower>
            <upper>3.14159</upper>
            <effort>114</effort>
            <velocity>12</velocity>
          </limit>
          <dynamics>
            <damping>1</damping>
            <friction>0</friction>
            <spring_reference>0</spring_reference>
            <spring_stiffness>0</spring_stiffness>
          </dynamics>
          <use_parent_model_frame>1</use_parent_model_frame>
        </axis>
        <physics>
          <ode>
            <implicit_spring_damper>1</implicit_spring_damper>
            <cfm_damping>1</cfm_damping>
            <limit>
              <cfm>0</cfm>
              <erp>0.2</erp>
            </limit>
          </ode>
        </physics>
      </joint>
      <link name='r_larm'>
        <pose frame=''>0.0115 -0.602 0.478 0 -0 0</pose>
        <inertial>
          <pose frame=''>-0.003 -0.099 -0.014 0 -0 0</pose>
          <mass>2.148</mass>
          <inertia>
            <ixx>0.005</ixx>
            <ixy>0</ixy>
            <ixz>0</ixz>
            <iyy>0.003</iyy>
            <iyz>0</iyz>
            <izz>0.006</izz>
          </inertia>
        </inertial>
        <collision name='r_larm_collision'>
          <pose frame=''>0.001 -0.127 0 1.5708 -0 0</pose>
          <geometry>
            <cylinder>
              <length>0.125</length>
              <radius>0.045</radius>
            </cylinder>
          </geometry>
          <surface>
            <contact>
              <ode/>
            </contact>
            <friction>
              <ode>
                <mu>0.9</mu>
                <mu2>0.9</mu2>
              </ode>
            </friction>
            <bounce/>
          </surface>
          <max_contacts>10</max_contacts>
        </collision>
        <collision name='r_larm_collision_r_larm_1'>
          <pose frame=''>0.001 -0.051 0 0 -0 0</pose>
          <geometry>
            <box>
              <size>0.135 0.15 0.06</size>
            </box>
          </geometry>
          <surface>
            <contact>
              <ode/>
            </contact>
            <friction>
              <ode>
                <mu>0.9</mu>
                <mu2>0.9</mu2>
              </ode>
            </friction>
            <bounce/>
          </surface>
          <max_contacts>10</max_contacts>
        </collision>
        <visual name='r_larm_visual'>
          <pose frame=''>0 0 0 0 -0 0</pose>
          <geometry>
            <mesh>
              <scale>1 1 1</scale>
              <uri>model://atlas_description/meshes/r_larm.dae</uri>
            </mesh>
          </geometry>
        </visual>
        <gravity>1</gravity>
        <velocity_decay/>
        <self_collide>0</self_collide>
        <kinematic>0</kinematic>
      </link>
      <joint name='r_arm_elx' type='revolute'>
        <child>r_larm</child>
        <parent>r_uarm</parent>
        <axis>
          <xyz>1 0 0</xyz>
          <limit>
            <lower>-2.35619</lower>
            <upper>0</upper>
            <effort>114</effort>
            <velocity>12</velocity>
          </limit>
          <dynamics>
            <damping>1</damping>
            <friction>0</friction>
            <spring_reference>0</spring_reference>
            <spring_stiffness>0</spring_stiffness>
          </dynamics>
          <use_parent_model_frame>1</use_parent_model_frame>
        </axis>
        <physics>
          <ode>
            <implicit_spring_damper>1</implicit_spring_damper>
            <cfm_damping>1</cfm_damping>
            <limit>
              <cfm>0</cfm>
              <erp>0.2</erp>
            </limit>
          </ode>
        </physics>
      </joint>
      <link name='r_farm'>
        <pose frame=''>0.0115 -0.79 0.465 0 -0 0</pose>
        <inertial>
          <pose frame=''>0 -0.041 0 0 -0 0</pose>
          <mass>0.981</mass>
          <inertia>
            <ixx>0.003</ixx>
            <ixy>0</ixy>
            <ixz>0</ixz>
            <iyy>0.001</iyy>
            <iyz>0</iyz>
            <izz>0.003</izz>
          </inertia>
        </inertial>
        <collision name='r_farm_collision'>
          <pose frame=''>0 -0.065 0.004 3.14159 1.57079 3.14159</pose>
          <geometry>
            <cylinder>
              <length>0.125</length>
              <radius>0.045</radius>
            </cylinder>
          </geometry>
          <surface>
            <contact>
              <ode/>
            </contact>
            <friction>
              <ode>
                <mu>0.9</mu>
                <mu2>0.9</mu2>
              </ode>
            </friction>
            <bounce/>
          </surface>
          <max_contacts>10</max_contacts>
        </collision>
        <collision name='r_farm_collision_r_farm_1'>
          <pose frame=''>0.001 -0.015 -0.002 0 -0 0</pose>
          <geometry>
            <box>
              <size>0.135 0.1 0.045</size>
            </box>
          </geometry>
          <surface>
            <contact>
              <ode/>
            </contact>
            <friction>
              <ode>
                <mu>0.9</mu>
                <mu2>0.9</mu2>
              </ode>
            </friction>
            <bounce/>
          </surface>
          <max_contacts>10</max_contacts>
        </collision>
        <visual name='r_farm_visual'>
          <pose frame=''>0 0.06 0 0 -0 0</pose>
          <geometry>
            <mesh>
              <scale>1 1 1</scale>
              <uri>model://atlas_description/meshes/r_farm.dae</uri>
            </mesh>
          </geometry>
        </visual>
        <gravity>1</gravity>
        <velocity_decay/>
        <self_collide>0</self_collide>
        <kinematic>0</kinematic>
      </link>
      <joint name='r_arm_uwy' type='revolute'>
        <child>r_farm</child>
        <parent>r_larm</parent>
        <axis>
          <xyz>0 1 0</xyz>
          <limit>
            <lower>-1.571</lower>
            <upper>1.571</upper>
            <effort>114</effort>
            <velocity>12</velocity>
          </limit>
          <dynamics>
            <damping>1</damping>
            <friction>0</friction>
            <spring_reference>0</spring_reference>
            <spring_stiffness>0</spring_stiffness>
          </dynamics>
          <use_parent_model_frame>1</use_parent_model_frame>
        </axis>
        <physics>
          <ode>
            <implicit_spring_damper>1</implicit_spring_damper>
            <cfm_damping>1</cfm_damping>
            <limit>
              <cfm>0</cfm>
              <erp>0.2</erp>
            </limit>
          </ode>
        </physics>
      </joint>
      <link name='r_hand'>
        <pose frame=''>0.0115 -0.848 0.465 0 -0 0</pose>
        <inertial>
          <pose frame=''>0 -0.093 0 0 -0 0</pose>
          <mass>2.263</mass>
          <inertia>
            <ixx>0.01</ixx>
            <ixy>0</ixy>
            <ixz>0</ixz>
            <iyy>0.002</iyy>
            <iyz>0</iyz>
            <izz>0.01</izz>
          </inertia>
        </inertial>
        <collision name='r_hand_collision'>
          <pose frame=''>0.001 -0.1 0.01 1.5708 -0 0</pose>
          <geometry>
            <cylinder>
              <length>0.05</length>
              <radius>0.03</radius>
            </cylinder>
          </geometry>
          <surface>
            <contact>
              <ode/>
            </contact>
            <friction>
              <ode>
                <mu>0.9</mu>
                <mu2>0.9</mu2>
              </ode>
            </friction>
            <bounce/>
          </surface>
          <max_contacts>10</max_contacts>
        </collision>
        <collision name='r_hand_collision_r_hand_1'>
          <pose frame=''>0.001 -0.05 0.01 0 -0 0</pose>
          <geometry>
            <box>
              <size>0.13 0.09 0.07</size>
            </box>
          </geometry>
          <surface>
            <contact>
              <ode/>
            </contact>
            <friction>
              <ode>
                <mu>0.9</mu>
                <mu2>0.9</mu2>
              </ode>
            </friction>
            <bounce/>
          </surface>
          <max_contacts>10</max_contacts>
        </collision>
        <visual name='r_hand_visual'>
          <pose frame=''>0 0 0 0 -0 0</pose>
          <geometry>
            <mesh>
              <scale>1 1 1</scale>
              <uri>model://atlas_description/meshes/r_hand.dae</uri>
            </mesh>
          </geometry>
        </visual>
        <gravity>1</gravity>
        <velocity_decay/>
        <self_collide>0</self_collide>
        <kinematic>0</kinematic>
      </link>
      <joint name='r_arm_mwx' type='revolute'>
        <child>r_hand</child>
        <parent>r_farm</parent>
        <axis>
          <xyz>1 0 0</xyz>
          <limit>
            <lower>-1.571</lower>
            <upper>0.436</upper>
            <effort>60</effort>
            <velocity>12</velocity>
          </limit>
          <dynamics>
            <damping>1</damping>
            <friction>0</friction>
            <spring_reference>0</spring_reference>
            <spring_stiffness>0</spring_stiffness>
          </dynamics>
          <use_parent_model_frame>1</use_parent_model_frame>
        </axis>
        <physics>
          <provide_feedback>1</provide_feedback>
          <ode>
            <provide_feedback>1</provide_feedback>
            <limit>
              <cfm>0</cfm>
              <erp>0.2</erp>
            </limit>
            <implicit_spring_damper>1</implicit_spring_damper>
            <cfm_damping>1</cfm_damping>
          </ode>
        </physics>
      </joint>
      <link name='l_uglut'>
        <pose frame=''>0 0.089 0 0 -0 0</pose>
        <inertial>
          <pose frame=''>0.00529262 -0.00344732 0.00313046 0 -0 0</pose>
          <mass>0.5166</mass>
          <inertia>
            <ixx>0.00074276</ixx>
            <ixy>-3.79607e-08</ixy>
            <ixz>-2.79549e-05</ixz>
            <iyy>0.000688179</iyy>
            <iyz>-3.2735e-08</iyz>
            <izz>0.00041242</izz>
          </inertia>
        </inertial>
        <collision name='l_uglut_collision'>
          <pose frame=''>0 0 0 -2.65359e-06 1.57079 -2.65359e-06</pose>
          <geometry>
            <cylinder>
              <length>0.078396</length>
              <radius>0.019096</radius>
            </cylinder>
          </geometry>
          <surface>
            <contact>
              <ode/>
            </contact>
            <friction>
              <ode>
                <mu>0.9</mu>
                <mu2>0.9</mu2>
              </ode>
            </friction>
            <bounce/>
          </surface>
          <max_contacts>10</max_contacts>
        </collision>
        <collision name='l_uglut_collision_l_uglut_1'>
          <pose frame=''>0 0 0 0 -0 0</pose>
          <geometry>
            <cylinder>
              <length>0.080842</length>
              <radius>0.019841</radius>
            </cylinder>
          </geometry>
          <surface>
            <contact>
              <ode/>
            </contact>
            <friction>
              <ode>
                <mu>0.9</mu>
                <mu2>0.9</mu2>
              </ode>
            </friction>
            <bounce/>
          </surface>
          <max_contacts>10</max_contacts>
        </collision>
        <visual name='l_uglut_visual'>
          <pose frame=''>0 0 0 0 -0 0</pose>
          <geometry>
            <mesh>
              <scale>1 1 1</scale>
              <uri>model://atlas_description/meshes/l_uglut.dae</uri>
            </mesh>
          </geometry>
        </visual>
        <gravity>1</gravity>
        <velocity_decay/>
        <self_collide>0</self_collide>
        <kinematic>0</kinematic>
      </link>
      <joint name='l_leg_uhz' type='revolute'>
        <child>l_uglut</child>
        <parent>pelvis</parent>
        <axis>
          <xyz>0 0 1</xyz>
          <limit>
            <lower>-0.32</lower>
            <upper>1.14</upper>
            <effort>110</effort>
            <velocity>12</velocity>
          </limit>
          <dynamics>
            <damping>1</damping>
            <friction>0</friction>
            <spring_reference>0</spring_reference>
            <spring_stiffness>0</spring_stiffness>
          </dynamics>
          <use_parent_model_frame>1</use_parent_model_frame>
        </axis>
        <physics>
          <ode>
            <implicit_spring_damper>1</implicit_spring_damper>
            <cfm_damping>1</cfm_damping>
            <limit>
              <cfm>0</cfm>
              <erp>0.2</erp>
            </limit>
          </ode>
        </physics>
      </joint>
      <link name='l_lglut'>
        <pose frame=''>0 0.089 0 0 -0 0</pose>
        <inertial>
          <pose frame=''>0.0133341 0.0170484 -0.0312052 0 -0 0</pose>
          <mass>0.69</mass>
          <inertia>
            <ixx>0.000691326</ixx>
            <ixy>-2.24344e-05</ixy>
            <ixz>2.50508e-06</ixz>
            <iyy>0.00126856</iyy>
            <iyz>0.000137862</iyz>
            <izz>0.00106487</izz>
          </inertia>
        </inertial>
        <collision name='l_lglut_collision'>
          <pose frame=''>0.049968 0.022488 -0.0501165 1.5708 -0 0</pose>
          <geometry>
            <cylinder>
              <length>0.060306</length>
              <radius>0.0200969</radius>
            </cylinder>
          </geometry>
          <surface>
            <contact>
              <ode/>
            </contact>
            <friction>
              <ode>
                <mu>0.9</mu>
                <mu2>0.9</mu2>
              </ode>
            </friction>
            <bounce/>
          </surface>
          <max_contacts>10</max_contacts>
        </collision>
        <collision name='l_lglut_collision_l_lglut_1'>
          <pose frame=''>0 0 0 -2.65359e-06 1.57079 -2.65359e-06</pose>
          <geometry>
            <cylinder>
              <length>0.12</length>
              <radius>0.02</radius>
            </cylinder>
          </geometry>
          <surface>
            <contact>
              <ode/>
            </contact>
            <friction>
              <ode>
                <mu>0.9</mu>
                <mu2>0.9</mu2>
              </ode>
            </friction>
            <bounce/>
          </surface>
          <max_contacts>10</max_contacts>
        </collision>
        <visual name='l_lglut_visual'>
          <pose frame=''>0 0 0 0 -0 0</pose>
          <geometry>
            <mesh>
              <scale>1 1 1</scale>
              <uri>model://atlas_description/meshes/l_lglut.dae</uri>
            </mesh>
          </geometry>
        </visual>
        <gravity>1</gravity>
        <velocity_decay/>
        <self_collide>0</self_collide>
        <kinematic>0</kinematic>
      </link>
      <joint name='l_leg_mhx' type='revolute'>
        <child>l_lglut</child>
        <parent>l_uglut</parent>
        <axis>
          <xyz>1 0 0</xyz>
          <limit>
            <lower>-0.47</lower>
            <upper>0.495</upper>
            <effort>180</effort>
            <velocity>12</velocity>
          </limit>
          <dynamics>
            <damping>1</damping>
            <friction>0</friction>
            <spring_reference>0</spring_reference>
            <spring_stiffness>0</spring_stiffness>
          </dynamics>
          <use_parent_model_frame>1</use_parent_model_frame>
        </axis>
        <physics>
          <ode>
            <implicit_spring_damper>1</implicit_spring_damper>
            <cfm_damping>1</cfm_damping>
            <limit>
              <cfm>0</cfm>
              <erp>0.2</erp>
            </limit>
          </ode>
        </physics>
      </joint>
      <link name='l_uleg'>
        <pose frame=''>0.05 0.089 -0.05 0 -0 0</pose>
        <inertial>
          <pose frame=''>0 0 -0.21 0 -0 0</pose>
          <mass>7.34</mass>
          <inertia>
            <ixx>0.09</ixx>
            <ixy>0</ixy>
            <ixz>0</ixz>
            <iyy>0.09</iyy>
            <iyz>0</iyz>
            <izz>0.02</izz>
          </inertia>
        </inertial>
        <collision name='l_uleg_collision'>
          <pose frame=''>-0.0179 0.02085 -0.13 0 -0 0</pose>
          <geometry>
            <cylinder>
              <length>0.1</length>
              <radius>0.1</radius>
            </cylinder>
          </geometry>
          <surface>
            <contact>
              <ode/>
            </contact>
            <friction>
              <ode>
                <mu>0.9</mu>
                <mu2>0.9</mu2>
              </ode>
            </friction>
            <bounce/>
          </surface>
          <max_contacts>10</max_contacts>
        </collision>
        <collision name='l_uleg_collision_l_uleg_1'>
          <pose frame=''>-0.03 0.01 -0.23 0 -0.3 0</pose>
          <geometry>
            <cylinder>
              <length>0.15</length>
              <radius>0.07</radius>
            </cylinder>
          </geometry>
          <surface>
            <contact>
              <ode/>
            </contact>
            <friction>
              <ode>
                <mu>0.9</mu>
                <mu2>0.9</mu2>
              </ode>
            </friction>
            <bounce/>
          </surface>
          <max_contacts>10</max_contacts>
        </collision>
        <collision name='l_uleg_collision_l_uleg_2'>
          <pose frame=''>-0.005 0.01 -0.23 0 0.3 0</pose>
          <geometry>
            <cylinder>
              <length>0.15</length>
              <radius>0.07</radius>
            </cylinder>
          </geometry>
          <surface>
            <contact>
              <ode/>
            </contact>
            <friction>
              <ode>
                <mu>0.9</mu>
                <mu2>0.9</mu2>
              </ode>
            </friction>
            <bounce/>
          </surface>
          <max_contacts>10</max_contacts>
        </collision>
        <collision name='l_uleg_collision_l_uleg_3'>
          <pose frame=''>-0.02 0.03 -0.23 -0.25 0 0</pose>
          <geometry>
            <cylinder>
              <length>0.15</length>
              <radius>0.07</radius>
            </cylinder>
          </geometry>
          <surface>
            <contact>
              <ode/>
            </contact>
            <friction>
              <ode>
                <mu>0.9</mu>
                <mu2>0.9</mu2>
              </ode>
            </friction>
            <bounce/>
          </surface>
          <max_contacts>10</max_contacts>
        </collision>
        <visual name='l_uleg_visual'>
          <pose frame=''>0 0 0 0 -0 0</pose>
          <geometry>
            <mesh>
              <scale>1 1 1</scale>
              <uri>model://atlas_description/meshes/l_uleg.dae</uri>
            </mesh>
          </geometry>
        </visual>
        <gravity>1</gravity>
        <velocity_decay/>
        <self_collide>0</self_collide>
        <kinematic>0</kinematic>
      </link>
      <joint name='l_leg_lhy' type='revolute'>
        <child>l_uleg</child>
        <parent>l_lglut</parent>
        <axis>
          <xyz>0 1 0</xyz>
          <limit>
            <lower>-1.75</lower>
            <upper>0.524</upper>
            <effort>260</effort>
            <velocity>12</velocity>
          </limit>
          <dynamics>
            <damping>1</damping>
            <friction>0</friction>
            <spring_reference>0</spring_reference>
            <spring_stiffness>0</spring_stiffness>
          </dynamics>
          <use_parent_model_frame>1</use_parent_model_frame>
        </axis>
        <physics>
          <ode>
            <implicit_spring_damper>1</implicit_spring_damper>
            <cfm_damping>1</cfm_damping>
            <limit>
              <cfm>0</cfm>
              <erp>0.2</erp>
            </limit>
          </ode>
        </physics>
      </joint>
      <link name='l_lleg'>
        <pose frame=''>0 0.089 -0.424 0 -0 0</pose>
        <inertial>
          <pose frame=''>0.001 0 -0.187 0 -0 0</pose>
          <mass>4.367</mass>
          <inertia>
            <ixx>0.077</ixx>
            <ixy>0</ixy>
            <ixz>-0.003</ixz>
            <iyy>0.076</iyy>
            <iyz>0</iyz>
            <izz>0.01</izz>
          </inertia>
        </inertial>
        <collision name='l_lleg_collision'>
          <pose frame=''>0.02 0.00295 -0.18 0 0.1 0</pose>
          <geometry>
            <cylinder>
              <length>0.4</length>
              <radius>0.07</radius>
            </cylinder>
          </geometry>
          <surface>
            <contact>
              <ode/>
            </contact>
            <friction>
              <ode>
                <mu>0.9</mu>
                <mu2>0.9</mu2>
              </ode>
            </friction>
            <bounce/>
          </surface>
          <max_contacts>10</max_contacts>
        </collision>
        <visual name='l_lleg_visual'>
          <pose frame=''>0 0 0 0 -0 0</pose>
          <geometry>
            <mesh>
              <scale>1 1 1</scale>
              <uri>model://atlas_description/meshes/l_lleg.dae</uri>
            </mesh>
          </geometry>
        </visual>
        <gravity>1</gravity>
        <velocity_decay/>
        <self_collide>0</self_collide>
        <kinematic>0</kinematic>
      </link>
      <joint name='l_leg_kny' type='revolute'>
        <child>l_lleg</child>
        <parent>l_uleg</parent>
        <axis>
          <xyz>0 1 0</xyz>
          <limit>
            <lower>0</lower>
            <upper>2.45</upper>
            <effort>400</effort>
            <velocity>12</velocity>
          </limit>
          <dynamics>
            <damping>1</damping>
            <friction>0</friction>
            <spring_reference>0</spring_reference>
            <spring_stiffness>0</spring_stiffness>
          </dynamics>
          <use_parent_model_frame>1</use_parent_model_frame>
        </axis>
        <physics>
          <ode>
            <implicit_spring_damper>1</implicit_spring_damper>
            <cfm_damping>1</cfm_damping>
            <limit>
              <cfm>0</cfm>
              <erp>0.2</erp>
            </limit>
          </ode>
        </physics>
      </joint>
      <link name='l_talus'>
        <pose frame=''>0 0.089 -0.846 0 -0 0</pose>
        <inertial>
          <pose frame=''>0 0 0 0 -0 0</pose>
          <mass>0.1</mass>
          <inertia>
            <ixx>1.01674e-05</ixx>
            <ixy>0</ixy>
            <ixz>0</ixz>
            <iyy>8.42775e-06</iyy>
            <iyz>0</iyz>
            <izz>1.30101e-05</izz>
          </inertia>
        </inertial>
        <collision name='l_talus_collision'>
          <pose frame=''>0 0 0 -2.65359e-06 1.57079 -2.65359e-06</pose>
          <geometry>
            <cylinder>
              <length>0.029542</length>
              <radius>0.010181</radius>
            </cylinder>
          </geometry>
          <surface>
            <contact>
              <ode/>
            </contact>
            <friction>
              <ode>
                <mu>0.9</mu>
                <mu2>0.9</mu2>
              </ode>
            </friction>
            <bounce/>
          </surface>
          <max_contacts>10</max_contacts>
        </collision>
        <collision name='l_talus_collision_l_talus_1'>
          <pose frame=''>0 0 0 1.5708 -0 0</pose>
          <geometry>
            <cylinder>
              <length>0.010059</length>
              <radius>0.010348</radius>
            </cylinder>
          </geometry>
          <surface>
            <contact>
              <ode/>
            </contact>
            <friction>
              <ode>
                <mu>0.9</mu>
                <mu2>0.9</mu2>
              </ode>
            </friction>
            <bounce/>
          </surface>
          <max_contacts>10</max_contacts>
        </collision>
        <visual name='l_talus_visual'>
          <pose frame=''>0 0 0 0 -0 0</pose>
          <geometry>
            <mesh>
              <scale>1 1 1</scale>
              <uri>model://atlas_description/meshes/l_talus.dae</uri>
            </mesh>
          </geometry>
        </visual>
        <gravity>1</gravity>
        <velocity_decay/>
        <self_collide>0</self_collide>
        <kinematic>0</kinematic>
      </link>
      <joint name='l_leg_uay' type='revolute'>
        <child>l_talus</child>
        <parent>l_lleg</parent>
        <axis>
          <xyz>0 1 0</xyz>
          <limit>
            <lower>-0.9</lower>
            <upper>0.698</upper>
            <effort>220</effort>
            <velocity>12</velocity>
          </limit>
          <dynamics>
            <damping>1</damping>
            <friction>0</friction>
            <spring_reference>0</spring_reference>
            <spring_stiffness>0</spring_stiffness>
          </dynamics>
          <use_parent_model_frame>1</use_parent_model_frame>
        </axis>
        <physics>
          <ode>
            <implicit_spring_damper>1</implicit_spring_damper>
            <cfm_damping>1</cfm_damping>
            <limit>
              <cfm>0</cfm>
              <erp>0.2</erp>
            </limit>
          </ode>
        </physics>
      </joint>
      <link name='l_foot'>
        <pose frame=''>0 0.089 -0.846 0 -0 0</pose>
        <inertial>
          <pose frame=''>0.027 0 -0.067 0 -0 0</pose>
          <mass>1.634</mass>
          <inertia>
            <ixx>0.002</ixx>
            <ixy>0</ixy>
            <ixz>0</ixz>
            <iyy>0.007</iyy>
            <iyz>0</iyz>
            <izz>0.008</izz>
          </inertia>
        </inertial>
        <collision name='l_foot_collision'>
          <pose frame=''>0.048 0 -0.056119 0 -0 0</pose>
          <geometry>
            <box>
              <size>0.26 0.124887 0.05</size>
            </box>
          </geometry>
          <surface>
            <contact>
              <ode>
                <kp>1e+06</kp>
                <kd>100</kd>
                <max_vel>1</max_vel>
                <min_depth>0</min_depth>
              </ode>
            </contact>
            <friction>
              <ode>
                <mu>1.5</mu>
                <mu2>1.5</mu2>
                <fdir1>1 0 0</fdir1>
              </ode>
            </friction>
            <bounce/>
          </surface>
          <surface>
            <contact>
              <ode/>
            </contact>
            <friction>
              <ode/>
            </friction>
          </surface>
          <max_contacts>10</max_contacts>
        </collision>
        <visual name='l_foot_visual'>
          <pose frame=''>0 0 0 0 -0 0</pose>
          <geometry>
            <mesh>
              <scale>1 1 1</scale>
              <uri>model://atlas_description/meshes/l_foot.dae</uri>
            </mesh>
          </geometry>
        </visual>
        <velocity_decay/>
        <gravity>1</gravity>
        <velocity_decay/>
        <self_collide>0</self_collide>
        <sensor name='l_foot_contact_sensor' type='contact'>
          <update_rate>1000</update_rate>
          <always_on>1</always_on>
          <contact>
            <collision>l_foot_collision</collision>
            <topic>/l_foot_contact</topic>
          </contact>
        </sensor>
        <kinematic>0</kinematic>
      </link>
      <joint name='l_leg_lax' type='revolute'>
        <child>l_foot</child>
        <parent>l_talus</parent>
        <axis>
          <xyz>1 0 0</xyz>
          <limit>
            <lower>-0.436</lower>
            <upper>0.436</upper>
            <effort>90</effort>
            <velocity>12</velocity>
          </limit>
          <dynamics>
            <damping>1</damping>
            <friction>0</friction>
            <spring_reference>0</spring_reference>
            <spring_stiffness>0</spring_stiffness>
          </dynamics>
          <use_parent_model_frame>1</use_parent_model_frame>
        </axis>
        <physics>
          <provide_feedback>1</provide_feedback>
          <ode>
            <provide_feedback>1</provide_feedback>
            <implicit_spring_damper>1</implicit_spring_damper>
            <cfm_damping>1</cfm_damping>
            <limit>
              <cfm>0</cfm>
              <erp>0.2</erp>
            </limit>
          </ode>
        </physics>
      </joint>
      <link name='r_uglut'>
        <pose frame=''>0 -0.089 0 0 -0 0</pose>
        <inertial>
          <pose frame=''>0.00529262 0.00344732 0.00313046 0 -0 0</pose>
          <mass>0.5166</mass>
          <inertia>
            <ixx>0.00074276</ixx>
            <ixy>3.79607e-08</ixy>
            <ixz>-2.79549e-05</ixz>
            <iyy>0.000688179</iyy>
            <iyz>3.2735e-08</iyz>
            <izz>0.00041242</izz>
          </inertia>
        </inertial>
        <collision name='r_uglut_collision'>
          <pose frame=''>0 0 0 -2.65359e-06 1.57079 -2.65359e-06</pose>
          <geometry>
            <cylinder>
              <length>0.078396</length>
              <radius>0.019096</radius>
            </cylinder>
          </geometry>
          <surface>
            <contact>
              <ode/>
            </contact>
            <friction>
              <ode>
                <mu>0.9</mu>
                <mu2>0.9</mu2>
              </ode>
            </friction>
            <bounce/>
          </surface>
          <max_contacts>10</max_contacts>
        </collision>
        <collision name='r_uglut_collision_r_uglut_1'>
          <pose frame=''>0 0 0 0 -0 0</pose>
          <geometry>
            <cylinder>
              <length>0.080842</length>
              <radius>0.019841</radius>
            </cylinder>
          </geometry>
          <surface>
            <contact>
              <ode/>
            </contact>
            <friction>
              <ode>
                <mu>0.9</mu>
                <mu2>0.9</mu2>
              </ode>
            </friction>
            <bounce/>
          </surface>
          <max_contacts>10</max_contacts>
        </collision>
        <visual name='r_uglut_visual'>
          <pose frame=''>0 0 0 0 -0 0</pose>
          <geometry>
            <mesh>
              <scale>1 1 1</scale>
              <uri>model://atlas_description/meshes/r_uglut.dae</uri>
            </mesh>
          </geometry>
        </visual>
        <gravity>1</gravity>
        <velocity_decay/>
        <self_collide>0</self_collide>
        <kinematic>0</kinematic>
      </link>
      <joint name='r_leg_uhz' type='revolute'>
        <child>r_uglut</child>
        <parent>pelvis</parent>
        <axis>
          <xyz>0 0 1</xyz>
          <limit>
            <lower>-1.14</lower>
            <upper>0.32</upper>
            <effort>110</effort>
            <velocity>12</velocity>
          </limit>
          <dynamics>
            <damping>1</damping>
            <friction>0</friction>
            <spring_reference>0</spring_reference>
            <spring_stiffness>0</spring_stiffness>
          </dynamics>
          <use_parent_model_frame>1</use_parent_model_frame>
        </axis>
        <physics>
          <ode>
            <implicit_spring_damper>1</implicit_spring_damper>
            <cfm_damping>1</cfm_damping>
            <limit>
              <cfm>0</cfm>
              <erp>0.2</erp>
            </limit>
          </ode>
        </physics>
      </joint>
      <link name='r_lglut'>
        <pose frame=''>0 -0.089 0 0 -0 0</pose>
        <inertial>
          <pose frame=''>0.0133341 -0.0170484 -0.0312052 0 -0 0</pose>
          <mass>0.69</mass>
          <inertia>
            <ixx>0.000691326</ixx>
            <ixy>2.24344e-05</ixy>
            <ixz>2.50508e-06</ixz>
            <iyy>0.00126856</iyy>
            <iyz>-0.000137862</iyz>
            <izz>0.00106487</izz>
          </inertia>
        </inertial>
        <collision name='r_lglut_collision'>
          <pose frame=''>0.049968 -0.022488 -0.0501165 1.5708 -0 0</pose>
          <geometry>
            <cylinder>
              <length>0.060306</length>
              <radius>0.0200969</radius>
            </cylinder>
          </geometry>
          <surface>
            <contact>
              <ode/>
            </contact>
            <friction>
              <ode>
                <mu>0.9</mu>
                <mu2>0.9</mu2>
              </ode>
            </friction>
            <bounce/>
          </surface>
          <max_contacts>10</max_contacts>
        </collision>
        <collision name='r_lglut_collision_r_lglut_1'>
          <pose frame=''>0 0 0 -2.65359e-06 1.57079 -2.65359e-06</pose>
          <geometry>
            <cylinder>
              <length>0.12</length>
              <radius>0.02</radius>
            </cylinder>
          </geometry>
          <surface>
            <contact>
              <ode/>
            </contact>
            <friction>
              <ode>
                <mu>0.9</mu>
                <mu2>0.9</mu2>
              </ode>
            </friction>
            <bounce/>
          </surface>
          <max_contacts>10</max_contacts>
        </collision>
        <visual name='r_lglut_visual'>
          <pose frame=''>0 0 0 0 -0 0</pose>
          <geometry>
            <mesh>
              <scale>1 1 1</scale>
              <uri>model://atlas_description/meshes/r_lglut.dae</uri>
            </mesh>
          </geometry>
        </visual>
        <gravity>1</gravity>
        <velocity_decay/>
        <self_collide>0</self_collide>
        <kinematic>0</kinematic>
      </link>
      <joint name='r_leg_mhx' type='revolute'>
        <child>r_lglut</child>
        <parent>r_uglut</parent>
        <axis>
          <xyz>1 0 0</xyz>
          <limit>
            <lower>-0.495</lower>
            <upper>0.47</upper>
            <effort>180</effort>
            <velocity>12</velocity>
          </limit>
          <dynamics>
            <damping>1</damping>
            <friction>0</friction>
            <spring_reference>0</spring_reference>
            <spring_stiffness>0</spring_stiffness>
          </dynamics>
          <use_parent_model_frame>1</use_parent_model_frame>
        </axis>
        <physics>
          <ode>
            <implicit_spring_damper>1</implicit_spring_damper>
            <cfm_damping>1</cfm_damping>
            <limit>
              <cfm>0</cfm>
              <erp>0.2</erp>
            </limit>
          </ode>
        </physics>
      </joint>
      <link name='r_uleg'>
        <pose frame=''>0.05 -0.089 -0.05 0 -0 0</pose>
        <inertial>
          <pose frame=''>0 0 -0.21 0 -0 0</pose>
          <mass>7.34</mass>
          <inertia>
            <ixx>0.09</ixx>
            <ixy>0</ixy>
            <ixz>0</ixz>
            <iyy>0.09</iyy>
            <iyz>0</iyz>
            <izz>0.02</izz>
          </inertia>
        </inertial>
        <collision name='r_uleg_collision'>
          <pose frame=''>-0.0179 -0.02085 -0.13 0 -0 0</pose>
          <geometry>
            <cylinder>
              <length>0.1</length>
              <radius>0.1</radius>
            </cylinder>
          </geometry>
          <surface>
            <contact>
              <ode/>
            </contact>
            <friction>
              <ode>
                <mu>0.9</mu>
                <mu2>0.9</mu2>
              </ode>
            </friction>
            <bounce/>
          </surface>
          <max_contacts>10</max_contacts>
        </collision>
        <collision name='r_uleg_collision_r_uleg_1'>
          <pose frame=''>-0.03 -0.01 -0.23 0 -0.3 0</pose>
          <geometry>
            <cylinder>
              <length>0.15</length>
              <radius>0.07</radius>
            </cylinder>
          </geometry>
          <surface>
            <contact>
              <ode/>
            </contact>
            <friction>
              <ode>
                <mu>0.9</mu>
                <mu2>0.9</mu2>
              </ode>
            </friction>
            <bounce/>
          </surface>
          <max_contacts>10</max_contacts>
        </collision>
        <collision name='r_uleg_collision_r_uleg_2'>
          <pose frame=''>-0.005 -0.01 -0.23 0 0.3 0</pose>
          <geometry>
            <cylinder>
              <length>0.15</length>
              <radius>0.07</radius>
            </cylinder>
          </geometry>
          <surface>
            <contact>
              <ode/>
            </contact>
            <friction>
              <ode>
                <mu>0.9</mu>
                <mu2>0.9</mu2>
              </ode>
            </friction>
            <bounce/>
          </surface>
          <max_contacts>10</max_contacts>
        </collision>
        <collision name='r_uleg_collision_r_uleg_3'>
          <pose frame=''>-0.02 -0.03 -0.23 0.25 -0 0</pose>
          <geometry>
            <cylinder>
              <length>0.15</length>
              <radius>0.07</radius>
            </cylinder>
          </geometry>
          <surface>
            <contact>
              <ode/>
            </contact>
            <friction>
              <ode>
                <mu>0.9</mu>
                <mu2>0.9</mu2>
              </ode>
            </friction>
            <bounce/>
          </surface>
          <max_contacts>10</max_contacts>
        </collision>
        <visual name='r_uleg_visual'>
          <pose frame=''>0 0 0 0 -0 0</pose>
          <geometry>
            <mesh>
              <scale>1 1 1</scale>
              <uri>model://atlas_description/meshes/r_uleg.dae</uri>
            </mesh>
          </geometry>
        </visual>
        <gravity>1</gravity>
        <velocity_decay/>
        <self_collide>0</self_collide>
        <kinematic>0</kinematic>
      </link>
      <joint name='r_leg_lhy' type='revolute'>
        <child>r_uleg</child>
        <parent>r_lglut</parent>
        <axis>
          <xyz>0 1 0</xyz>
          <limit>
            <lower>-1.745</lower>
            <upper>0.524</upper>
            <effort>260</effort>
            <velocity>12</velocity>
          </limit>
          <dynamics>
            <damping>1</damping>
            <friction>0</friction>
            <spring_reference>0</spring_reference>
            <spring_stiffness>0</spring_stiffness>
          </dynamics>
          <use_parent_model_frame>1</use_parent_model_frame>
        </axis>
        <physics>
          <ode>
            <implicit_spring_damper>1</implicit_spring_damper>
            <cfm_damping>1</cfm_damping>
            <limit>
              <cfm>0</cfm>
              <erp>0.2</erp>
            </limit>
          </ode>
        </physics>
      </joint>
      <link name='r_lleg'>
        <pose frame=''>0 -0.089 -0.424 0 -0 0</pose>
        <inertial>
          <pose frame=''>0.001 0 -0.187 0 -0 0</pose>
          <mass>4.367</mass>
          <inertia>
            <ixx>0.077</ixx>
            <ixy>-0</ixy>
            <ixz>-0.003</ixz>
            <iyy>0.076</iyy>
            <iyz>-0</iyz>
            <izz>0.01</izz>
          </inertia>
        </inertial>
        <collision name='r_lleg_collision'>
          <pose frame=''>0.02 -0.00295 -0.18 0 0.1 0</pose>
          <geometry>
            <cylinder>
              <length>0.4</length>
              <radius>0.07</radius>
            </cylinder>
          </geometry>
          <surface>
            <contact>
              <ode/>
            </contact>
            <friction>
              <ode>
                <mu>0.9</mu>
                <mu2>0.9</mu2>
              </ode>
            </friction>
            <bounce/>
          </surface>
          <max_contacts>10</max_contacts>
        </collision>
        <visual name='r_lleg_visual'>
          <pose frame=''>0 0 0 0 -0 0</pose>
          <geometry>
            <mesh>
              <scale>1 1 1</scale>
              <uri>model://atlas_description/meshes/r_lleg.dae</uri>
            </mesh>
          </geometry>
        </visual>
        <gravity>1</gravity>
        <velocity_decay/>
        <self_collide>0</self_collide>
        <kinematic>0</kinematic>
      </link>
      <joint name='r_leg_kny' type='revolute'>
        <child>r_lleg</child>
        <parent>r_uleg</parent>
        <axis>
          <xyz>0 1 0</xyz>
          <limit>
            <lower>0</lower>
            <upper>2.45</upper>
            <effort>400</effort>
            <velocity>12</velocity>
          </limit>
          <dynamics>
            <damping>1</damping>
            <friction>0</friction>
            <spring_reference>0</spring_reference>
            <spring_stiffness>0</spring_stiffness>
          </dynamics>
          <use_parent_model_frame>1</use_parent_model_frame>
        </axis>
        <physics>
          <ode>
            <implicit_spring_damper>1</implicit_spring_damper>
            <cfm_damping>1</cfm_damping>
            <limit>
              <cfm>0</cfm>
              <erp>0.2</erp>
            </limit>
          </ode>
        </physics>
      </joint>
      <link name='r_talus'>
        <pose frame=''>0 -0.089 -0.846 0 -0 0</pose>
        <inertial>
          <pose frame=''>0 0 0 0 -0 0</pose>
          <mass>0.1</mass>
          <inertia>
            <ixx>1.01674e-05</ixx>
            <ixy>0</ixy>
            <ixz>0</ixz>
            <iyy>8.42775e-06</iyy>
            <iyz>0</iyz>
            <izz>1.30101e-05</izz>
          </inertia>
        </inertial>
        <collision name='r_talus_collision'>
          <pose frame=''>0 0 0 -2.65359e-06 1.57079 -2.65359e-06</pose>
          <geometry>
            <cylinder>
              <length>0.029542</length>
              <radius>0.010181</radius>
            </cylinder>
          </geometry>
          <surface>
            <contact>
              <ode/>
            </contact>
            <friction>
              <ode>
                <mu>0.9</mu>
                <mu2>0.9</mu2>
              </ode>
            </friction>
            <bounce/>
          </surface>
          <max_contacts>10</max_contacts>
        </collision>
        <collision name='r_talus_collision_r_talus_1'>
          <pose frame=''>0 0 0 1.5708 -0 0</pose>
          <geometry>
            <cylinder>
              <length>0.010059</length>
              <radius>0.010348</radius>
            </cylinder>
          </geometry>
          <surface>
            <contact>
              <ode/>
            </contact>
            <friction>
              <ode>
                <mu>0.9</mu>
                <mu2>0.9</mu2>
              </ode>
            </friction>
            <bounce/>
          </surface>
          <max_contacts>10</max_contacts>
        </collision>
        <visual name='r_talus_visual'>
          <pose frame=''>0 0 0 0 -0 0</pose>
          <geometry>
            <mesh>
              <scale>1 1 1</scale>
              <uri>model://atlas_description/meshes/r_talus.dae</uri>
            </mesh>
          </geometry>
        </visual>
        <gravity>1</gravity>
        <velocity_decay/>
        <self_collide>0</self_collide>
        <kinematic>0</kinematic>
      </link>
      <joint name='r_leg_uay' type='revolute'>
        <child>r_talus</child>
        <parent>r_lleg</parent>
        <axis>
          <xyz>0 1 0</xyz>
          <limit>
            <lower>-0.9</lower>
            <upper>0.698</upper>
            <effort>220</effort>
            <velocity>12</velocity>
          </limit>
          <dynamics>
            <damping>1</damping>
            <friction>0</friction>
            <spring_reference>0</spring_reference>
            <spring_stiffness>0</spring_stiffness>
          </dynamics>
          <use_parent_model_frame>1</use_parent_model_frame>
        </axis>
        <physics>
          <ode>
            <implicit_spring_damper>1</implicit_spring_damper>
            <cfm_damping>1</cfm_damping>
            <limit>
              <cfm>0</cfm>
              <erp>0.2</erp>
            </limit>
          </ode>
        </physics>
      </joint>
      <link name='r_foot'>
        <pose frame=''>0 -0.089 -0.846 0 -0 0</pose>
        <inertial>
          <pose frame=''>0.027 0 -0.067 0 -0 0</pose>
          <mass>1.634</mass>
          <inertia>
            <ixx>0.002</ixx>
            <ixy>0</ixy>
            <ixz>0</ixz>
            <iyy>0.007</iyy>
            <iyz>0</iyz>
            <izz>0.008</izz>
          </inertia>
        </inertial>
        <collision name='r_foot_collision'>
          <pose frame=''>0.048 0 -0.056119 0 -0 0</pose>
          <geometry>
            <box>
              <size>0.26 0.124887 0.05</size>
            </box>
          </geometry>
          <surface>
            <contact>
              <ode>
                <kp>1e+06</kp>
                <kd>100</kd>
                <max_vel>1</max_vel>
                <min_depth>0</min_depth>
              </ode>
            </contact>
            <friction>
              <ode>
                <mu>1.5</mu>
                <mu2>1.5</mu2>
                <fdir1>1 0 0</fdir1>
              </ode>
            </friction>
            <bounce/>
          </surface>
          <surface>
            <contact>
              <ode/>
            </contact>
            <friction>
              <ode/>
            </friction>
          </surface>
          <max_contacts>10</max_contacts>
        </collision>
        <visual name='r_foot_visual'>
          <pose frame=''>0 0 0 0 -0 0</pose>
          <geometry>
            <mesh>
              <scale>1 1 1</scale>
              <uri>model://atlas_description/meshes/r_foot.dae</uri>
            </mesh>
          </geometry>
        </visual>
        <velocity_decay/>
        <gravity>1</gravity>
        <velocity_decay/>
        <self_collide>0</self_collide>
        <sensor name='r_foot_contact_sensor' type='contact'>
          <update_rate>1000</update_rate>
          <always_on>1</always_on>
          <contact>
            <collision>r_foot_collision</collision>
            <topic>/r_foot_contact</topic>
          </contact>
        </sensor>
        <kinematic>0</kinematic>
      </link>
      <joint name='r_leg_lax' type='revolute'>
        <child>r_foot</child>
        <parent>r_talus</parent>
        <axis>
          <xyz>1 0 0</xyz>
          <limit>
            <lower>-0.436</lower>
            <upper>0.436</upper>
            <effort>90</effort>
            <velocity>12</velocity>
          </limit>
          <dynamics>
            <damping>1</damping>
            <friction>0</friction>
            <spring_reference>0</spring_reference>
            <spring_stiffness>0</spring_stiffness>
          </dynamics>
          <use_parent_model_frame>1</use_parent_model_frame>
        </axis>
        <physics>
          <provide_feedback>1</provide_feedback>
          <ode>
            <provide_feedback>1</provide_feedback>
            <implicit_spring_damper>1</implicit_spring_damper>
            <cfm_damping>1</cfm_damping>
            <limit>
              <cfm>0</cfm>
              <erp>0.2</erp>
            </limit>
          </ode>
        </physics>
      </joint>
      <pose frame=''>0 0 0.93 0 -0 0</pose>
      <plugin name='atlas_plugin' filename='libAtlasPlugin.so'/>
      <plugin name='joint_trajectory_plugin' filename='libgazebo_ros_joint_pose_trajectory.so'>
        <topicName>joint_trajectory</topicName>
        <updateRate>1000.0</updateRate>
      </plugin>
      <plugin name='gazebo_ros_p3d' filename='libgazebo_ros_p3d.so'>
        <bodyName>pelvis</bodyName>
        <topicName>/ground_truth_odom</topicName>
        <alwaysOn>true</alwaysOn>
        <updateRate>100.0</updateRate>
      </plugin>
      <plugin name='gazebo_ros_force' filename='libgazebo_ros_force.so'>
        <bodyName>pelvis</bodyName>
        <topicName>/atlas/apply_pelvis_force</topicName>
      </plugin>
      <static>0</static>
      <plugin name='multisense_plugin' filename='libMultiSenseSLPlugin.so'/>
    </model>
    <light name='user_point_light_0' type='point'>
      <pose frame=''>7.48576 0.561381 1 0 -0 0</pose>
      <diffuse>0.5 0.5 0.5 1</diffuse>
      <specular>0.1 0.1 0.1 1</specular>
      <attenuation>
        <range>20</range>
        <constant>0.5</constant>
        <linear>0.01</linear>
        <quadratic>0.001</quadratic>
      </attenuation>
      <cast_shadows>0</cast_shadows>
      <direction>0 0 -1</direction>
    </light>
  </world>
</sdf>
